Workbook

Sheet BULLETIN
A1: REPUBLIQUE DEMOCRATIQUE DU CONGO MINISTERE DE L'ENSEIGNEMENT PRIMAIRE, SECONDAIRE ET TECHNIQUE
A2: N° ID
A4: =IF(H4<>"",VLOOKUP(H4,LISTE!A3:EM72,8,FALSE),"") -> Lubumbashi | H4: KALABA KAMBA Chadrack
A5: =IF(H4<>"",VLOOKUP(H4,LISTE!A3:EM72,9,FALSE),"") -> Kamalondo | H5: =IF(H4<>"",VLOOKUP(H4,LISTE!A3:EM72,4,FALSE),"") -> 40529
A6: =IF(H4<>"",VLOOKUP(H4,LISTE!A3:EM72,10,FALSE),"") -> C.S EXCEL | H6: =IF(H4<>"",VLOOKUP(H4,LISTE!A3:EM72,5,FALSE),"") -> 2ème H.P | M6: =IF(H4<>"",VLOOKUP(H4,LISTE!A3:EM72,3,FALSE),"") -> M
A7: =IF(H4<>"",VLOOKUP(H4,LISTE!A3:EM72,11,FALSE),"") -> 710004 | H7: =IF(H4<>"",VLOOKUP(H4,LISTE!A3:EM72,6,FALSE),"") -> PERM04
A8: BULLETIN DE LA 2ème ANNEE HUMANITE PEDAGOGIE GENERALE ANNEE SCOLAIRE 20….. - 20…..
A9: BRANCHES | B9: PREMIER SEMESTRE | F9: SECOND SEMESTRE | J9: T.G | L9: EXAMEN DE REPECHAGE
B10: TR. JOURNAL. | D10: EXAM | E10: TOT | F10: TR. JOURNAL. | H10: EXAM | I10: TOT
B11: 1è P | C11: 2è P | F11: 3è P | G11: 4è P | L11: % | M11: Signature Prof.
A12: MAXIMA | B12: 10 | C12: 10 | D12: 20 | E12: 40 | F12: 10 | G12: 10 | H12: 20 | I12: 40 | J12: 80
A13: =LISTE!L1 -> Religion | B13: =IF(H4<>"",VLOOKUP(H4,LISTE!A3:EM72,12,FALSE),"") -> 5 | C13: =IF(H4<>"",VLOOKUP(H4,LISTE!A3:EM72,13,FALSE),"") -> 7 | D13: =IF(H4<>"",VLOOKUP(H4,LISTE!A3:EM72,14,FALSE),"") -> 10 | E13: =SUM(B13:D13) -> 22 | F13: =IF(H4<>"",VLOOKUP(H4,LISTE!A3:EM72,15,FALSE),"") -> 8 | G13: =IF(H4<>"",VLOOKUP(H4,LISTE!A3:EM72,16,FALSE),"") -> 5 | H13: =IF(H4<>"",VLOOKUP(H4,LISTE!A3:EM72,17,FALSE),"") -> 10 | I13: =SUM(F13:H13) -> 23 | J13: =E13+I13 -> 45
A14: =LISTE!R1 -> Education à la vie | B14: =IF(H4<>"",VLOOKUP(H4,LISTE!A3:EM72,18,FALSE),"") -> 5 | C14: =IF(H4<>"",VLOOKUP(H4,LISTE!A3:EM72,19,FALSE),"") -> 7 | D14: =IF(H4<>"",VLOOKUP(H4,LISTE!A3:EM72,20,FALSE),"") -> 12 | E14: =SUM(B14:D14) -> 24 | F14: =IF(H4<>"",VLOOKUP(H4,LISTE!A3:EM72,21,FALSE),"") -> 6 | G14: =IF(H4<>"",VLOOKUP(H4,LISTE!A3:EM72,22,FALSE),"") -> 7 | H14: =IF(H4<>"",VLOOKUP(H4,LISTE!A3:EM72,23,FALSE),"") -> 9 | I14: =SUM(F14:H14) -> 22 | J14: =E14+I14 -> 46
A15: =LISTE!X1 -> Ed. Civ & Morale | B15: =IF(H4<>"",VLOOKUP(H4,LISTE!A3:EM72,24,FALSE),"") -> 5 | C15: =IF(H4<>"",VLOOKUP(H4,LISTE!A3:EM72,25,FALSE),"") -> 8 | D15: =IF(H4<>"",VLOOKUP(H4,LISTE!A3:EM72,26,FALSE),"") -> 11 | E15: =SUM(B15:D15) -> 24 | F15: =IF(H4<>"",VLOOKUP(H4,LISTE!A3:EM72,27,FALSE),"") -> 6 | G15: =IF(H4<>"",VLOOKUP(H4,LISTE!A3:EM72,28,FALSE),"") -> 4 | H15: =IF(H4<>"",VLOOKUP(H4,LISTE!A3:EM72,29,FALSE),"") -> 9 | I15: =SUM(F15:H15) -> 19 | J15: =E15+I15 -> 43
A16: MAXIMA | B16: 20 | C16: 20 | D16: 40 | E16: 80 | F16: 20 | G16: 20 | H16: 40 | I16: 80 | J16: 160
A17: =LISTE!AD1 -> Chimie | B17: =IF(H4<>"",VLOOKUP(H4,LISTE!A3:EM72,30,FALSE),"") -> 5 | C17: =IF(H4<>"",VLOOKUP(H4,LISTE!A3:EM72,31,FALSE),"") -> 8 | D17: =IF(H4<>"",VLOOKUP(H4,LISTE!A3:EM72,32,FALSE),"") -> 11 | E17: =SUM(B17:D17) -> 24 | F17: =IF(H4<>"",VLOOKUP(H4,LISTE!A3:EM72,33,FALSE),"") -> 6 | G17: =IF(H4<>"",VLOOKUP(H4,LISTE!A3:EM72,34,FALSE),"") -> 4 | H17: =IF(H4<>"",VLOOKUP(H4,LISTE!A3:EM72,35,FALSE),"") -> 11 | I17: =SUM(F17:H17) -> 21 | J17: =SUM(E17,I17) -> 45
A18: =LISTE!AJ1 -> Dessin | B18: =IF(H4<>"",VLOOKUP(H4,LISTE!A3:EM72,36,FALSE),"") -> 9 | C18: =IF(H4<>"",VLOOKUP(H4,LISTE!A3:EM72,37,FALSE),"") -> 17 | D18: =IF(H4<>"",VLOOKUP(H4,LISTE!A3:EM72,38,FALSE),"") -> 22 | E18: =SUM(B18:D18) -> 48 | F18: =IF(H4<>"",VLOOKUP(H4,LISTE!A3:EM72,39,FALSE),"") -> 9 | G18: =IF(H4<>"",VLOOKUP(H4,LISTE!A3:EM72,40,FALSE),"") -> 10 | H18: =IF(H4<>"",VLOOKUP(H4,LISTE!A3:EM72,41,FALSE),"") -> 21 | I18: =SUM(F18:H18) -> 40 | J18: =SUM(E18,I18) -> 88
A19: =LISTE!$AP$1 -> Education physique | B19: =IF(H4<>"",VLOOKUP(H4,LISTE!A3:EM72,42,FALSE),"") -> 11 | C19: =IF(H4<>"",VLOOKUP(H4,LISTE!A3:EM72,43,FALSE),"") -> 11 | D19: =IF(H4<>"",VLOOKUP(H4,LISTE!A3:EM72,44,FALSE),"") -> 24 | E19: =SUM(B19:D19) -> 46 | F19: =IF(H4<>"",VLOOKUP(H4,LISTE!A3:EM72,45,FALSE),"") -> 12 | G19: =IF(H4<>"",VLOOKUP(H4,LISTE!A3:EM72,46,FALSE),"") -> 10 | H19: =IF(H4<>"",VLOOKUP(H4,LISTE!A3:EM72,47,FALSE),"") -> 21 | I19: =SUM(F19:H19) -> 43 | J19: =SUM(E19,I19) -> 89
A20: =LISTE!AV1 -> Economie politique | B20: =IF(H4<>"",VLOOKUP(H4,LISTE!A3:EM72,48,FALSE),"") -> 11 | C20: =IF(H4<>"",VLOOKUP(H4,LISTE!A3:EM72,49,FALSE),"") -> 11 | D20: =IF(H4<>"",VLOOKUP(H4,LISTE!A3:EM72,50,FALSE),"") -> 24 | E20: =SUM(B20:D20) -> 46 | F20: =IF(H4<>"",VLOOKUP(H4,LISTE!A3:EM72,51,FALSE),"") -> 12 | G20: =IF(H4<>"",VLOOKUP(H4,LISTE!A3:EM72,52,FALSE),"") -> 10 | H20: =IF(H4<>"",VLOOKUP(H4,LISTE!A3:EM72,53,FALSE),"") -> 21 | I20: =SUM(F20:H20) -> 43 | J20: =SUM(E20,I20) -> 89
A21: =LISTE!BB1 -> Education music. /Théatrale | B21: =IF(H4<>"",VLOOKUP(H4,LISTE!A3:EM72,54,FALSE),"") -> 9 | C21: =IF(H4<>"",VLOOKUP(H4,LISTE!A3:EM72,55,FALSE),"") -> 10 | D21: =IF(H4<>"",VLOOKUP(H4,LISTE!A3:EM72,56,FALSE),"") -> 24 | E21: =SUM(B21:D21) -> 43 | F21: =IF(H4<>"",VLOOKUP(H4,LISTE!A3:EM72,57,FALSE),"") -> 10 | G21: =IF(H4<>"",VLOOKUP(H4,LISTE!A3:EM72,58,FALSE),"") -> 11 | H21: =IF(H4<>"",VLOOKUP(H4,LISTE!A3:EM72,59,FALSE),"") -> 22 | I21: =SUM(F21:H21) -> 43 | J21: =SUM(E21,I21) -> 86
A22: =LISTE!BH1 -> Geographie | B22: =IF(H4<>"",VLOOKUP(H4,LISTE!A3:EM72,60,FALSE),"") -> 9 | C22: =IF(H4<>"",VLOOKUP(H4,LISTE!A3:EM72,61,FALSE),"") -> 10 | D22: =IF(H4<>"",VLOOKUP(H4,LISTE!A3:EM72,62,FALSE),"") -> 21 | E22: =SUM(B22:D22) -> 40 | F22: =IF(H4<>"",VLOOKUP(H4,LISTE!A3:EM72,63,FALSE),"") -> 11 | G22: =IF(H4<>"",VLOOKUP(H4,LISTE!A3:EM72,64,FALSE),"") -> 12 | H22: =IF(H4<>"",VLOOKUP(H4,LISTE!A3:EM72,65,FALSE),"") -> 16 | I22: =SUM(F22:H22) -> 39 | J22: =SUM(E22,I22) -> 79
A23: =LISTE!BN1 -> Histoire | B23: =IF(H4<>"",VLOOKUP(H4,LISTE!A3:EM72,66,FALSE),"") -> 11 | C23: =IF(H4<>"",VLOOKUP(H4,LISTE!A3:EM72,67,FALSE),"") -> 11 | D23: =IF(H4<>"",VLOOKUP(H4,LISTE!A3:EM72,68,FALSE),"") -> 29 | E23: =SUM(B23:D23) -> 51 | F23: =IF(H4<>"",VLOOKUP(H4,LISTE!A3:EM72,69,FALSE),"") -> 12 | G23: =IF(H4<>"",VLOOKUP(H4,LISTE!A3:EM72,70,FALSE),"") -> 9 | H23: =IF(H4<>"",VLOOKUP(H4,LISTE!A3:EM72,71,FALSE),"") -> 24 | I23: =SUM(F23:H23) -> 45 | J23: =SUM(E23,I23) -> 96
A24: =LISTE!$BT$1 -> Informatique | B24: =IF(H4<>"",VLOOKUP(H4,LISTE!A3:EM72,72,FALSE),"") -> 11 | C24: =IF(H4<>"",VLOOKUP(H4,LISTE!A3:EM72,73,FALSE),"") -> 13 | D24: =IF(H4<>"",VLOOKUP(H4,LISTE!A3:EM72,74,FALSE),"") -> 0 | E24: =SUM(B24:D24) -> 24 | F24: =IF(H4<>"",VLOOKUP(H4,LISTE!A3:EM72,75,FALSE),"") -> 9 | G24: =IF(H4<>"",VLOOKUP(H4,LISTE!A3:EM72,76,FALSE),"") -> 12 | H24: =IF(H4<>"",VLOOKUP(H4,LISTE!A3:EM72,77,FALSE),"") -> 0 | I24: =SUM(F24:H24) -> 21 | J24: =SUM(E24,I24) -> 45
A25: =LISTE!$BZ$1 -> Langues nationales | B25: =IF(H4<>"",VLOOKUP(H4,LISTE!A3:EM72,78,FALSE),"") -> 11 | C25: =IF(H4<>"",VLOOKUP(H4,LISTE!A3:EM72,79,FALSE),"") -> 11 | D25: =IF(H4<>"",VLOOKUP(H4,LISTE!A3:EM72,80,FALSE),"") -> 29 | E25: =SUM(B25:D25) -> 51 | F25: =IF(H4<>"",VLOOKUP(H4,LISTE!A3:EM72,81,FALSE),"") -> 12 | G25: =IF(H4<>"",VLOOKUP(H4,LISTE!A3:EM72,82,FALSE),"") -> 9 | H25: =IF(H4<>"",VLOOKUP(H4,LISTE!A3:EM72,83,FALSE),"") -> 24 | I25: =SUM(F25:H25) -> 45 | J25: =SUM(E25,I25) -> 96
A26: =LISTE!$CF$1 -> Microbiologie | B26: =IF(H4<>"",VLOOKUP(H4,LISTE!A3:EM72,84,FALSE),"") -> 11 | C26: =IF(H4<>"",VLOOKUP(H4,LISTE!A3:EM72,85,FALSE),"") -> 11 | D26: =IF(H4<>"",VLOOKUP(H4,LISTE!A3:EM72,86,FALSE),"") -> 29 | E26: =SUM(B26:D26) -> 51 | F26: =IF(H4<>"",VLOOKUP(H4,LISTE!A3:EM72,87,FALSE),"") -> 12 | G26: =IF(H4<>"",VLOOKUP(H4,LISTE!A3:EM72,88,FALSE),"") -> 9 | H26: =IF(H4<>"",VLOOKUP(H4,LISTE!A3:EM72,89,FALSE),"") -> 24 | I26: =SUM(F26:H26) -> 45 | J26: =SUM(E26,I26) -> 96
A27: =LISTE!CL1 -> Physique | B27: =IF(H4<>"",VLOOKUP(H4,LISTE!A3:EM72,90,FALSE),"") -> 11 | C27: =IF(H4<>"",VLOOKUP(H4,LISTE!A3:EM72,91,FALSE),"") -> 11 | D27: =IF(H4<>"",VLOOKUP(H4,LISTE!A3:EM72,92,FALSE),"") -> 29 | E27: =SUM(B27:D27) -> 51 | F27: =IF(H4<>"",VLOOKUP(H4,LISTE!A3:EM72,93,FALSE),"") -> 12 | G27: =IF(H4<>"",VLOOKUP(H4,LISTE!A3:EM72,94,FALSE),"") -> 9 | H27: =IF(H4<>"",VLOOKUP(H4,LISTE!A3:EM72,95,FALSE),"") -> 24 | I27: =SUM(F27:H27) -> 45 | J27: =SUM(E27,I27) -> 96
A28: MAXIMA | B28: 40 | C28: 40 | D28: 80 | E28: 160 | F28: 40 | G28: 40 | H28: 80 | I28: 160 | J28: 320
A29: =LISTE!$CR$1 -> Didactiques des disciplines | B29: =IF(H4<>"",VLOOKUP(H4,LISTE!A3:EM72,96,FALSE),"") -> 14 | C29: =IF(H4<>"",VLOOKUP(H4,LISTE!A3:EM72,97,FALSE),"") -> 10 | D29: =IF(H4<>"",VLOOKUP(H4,LISTE!A3:EM72,98,FALSE),"") -> 0 | E29: =SUM(B29:D29) -> 24 | F29: =IF(H4<>"",VLOOKUP(H4,LISTE!A3:EM72,99,FALSE),"") -> 9 | G29: =IF(H4<>"",VLOOKUP(H4,LISTE!A3:EM72,100,FALSE),"") -> 11 | H29: =IF(H4<>"",VLOOKUP(H4,LISTE!A3:EM72,101,FALSE),"") -> 0 | I29: =SUM(F29:H29) -> 20 | J29: =SUM(E29,I29) -> 44
A30: =LISTE!$CX$1 -> Didactique générale | B30: =IF(H4<>"",VLOOKUP(H4,LISTE!A3:EM72,102,FALSE),"") -> 11 | C30: =IF(H4<>"",VLOOKUP(H4,LISTE!A3:EM72,103,FALSE),"") -> 15 | D30: =IF(H4<>"",VLOOKUP(H4,LISTE!A3:EM72,104,FALSE),"") -> 0 | E30: =SUM(B30:D30) -> 26 | F30: =IF(H4<>"",VLOOKUP(H4,LISTE!A3:EM72,105,FALSE),"") -> 11 | G30: =IF(H4<>"",VLOOKUP(H4,LISTE!A3:EM72,106,FALSE),"") -> 9 | H30: =IF(H4<>"",VLOOKUP(H4,LISTE!A3:EM72,107,FALSE),"") -> 0 | I30: =SUM(F30:H30) -> 20 | J30: =SUM(E30,I30) -> 46
A31: =LISTE!$DD$1 -> Mathématiques | B31: =IF(H4<>"",VLOOKUP(H4,LISTE!A3:EM72,108,FALSE),"") -> 22 | C31: =IF(H4<>"",VLOOKUP(H4,LISTE!A3:EM72,109,FALSE),"") -> 20 | D31: =IF(H4<>"",VLOOKUP(H4,LISTE!A3:EM72,110,FALSE),"") -> 45 | E31: =SUM(B31:D31) -> 87 | F31: =IF(H4<>"",VLOOKUP(H4,LISTE!A3:EM72,111,FALSE),"") -> 21 | G31: =IF(H4<>"",VLOOKUP(H4,LISTE!A3:EM72,112,FALSE),"") -> 21 | H31: =IF(H4<>"",VLOOKUP(H4,LISTE!A3:EM72,113,FALSE),"") -> 40 | I31: =SUM(F31:H31) -> 82 | J31: =SUM(E31,I31) -> 169
A32: =LISTE!$DJ$1 -> Pédagogie | B32: =IF(H4<>"",VLOOKUP(H4,LISTE!A3:EM72,114,FALSE),"") -> 14 | C32: =IF(H4<>"",VLOOKUP(H4,LISTE!A3:EM72,115,FALSE),"") -> 10 | D32: =IF(H4<>"",VLOOKUP(H4,LISTE!A3:EM72,116,FALSE),"") -> 0 | E32: =SUM(B32:D32) -> 24 | F32: =IF(H4<>"",VLOOKUP(H4,LISTE!A3:EM72,117,FALSE),"") -> 9 | G32: =IF(H4<>"",VLOOKUP(H4,LISTE!A3:EM72,118,FALSE),"") -> 11 | H32: =IF(H4<>"",VLOOKUP(H4,LISTE!A3:EM72,119,FALSE),"") -> 0 | I32: =SUM(F32:H32) -> 20 | J32: =SUM(E32,I32) -> 44
A33: =LISTE!DP1 -> Psychologie | B33: =IF(H4<>"",VLOOKUP(H4,LISTE!A3:EM72,120,FALSE),"") -> 14 | C33: =IF(H4<>"",VLOOKUP(H4,LISTE!A3:EM72,121,FALSE),"") -> 10 | D33: =IF(H4<>"",VLOOKUP(H4,LISTE!A3:EM72,122,FALSE),"") -> 0 | E33: =SUM(B33:D33) -> 24 | F33: =IF(H4<>"",VLOOKUP(H4,LISTE!A3:EM72,123,FALSE),"") -> 9 | G33: =IF(H4<>"",VLOOKUP(H4,LISTE!A3:EM72,124,FALSE),"") -> 11 | H33: =IF(H4<>"",VLOOKUP(H4,LISTE!A3:EM72,125,FALSE),"") -> 0 | I33: =SUM(F33:H33) -> 20 | J33: =SUM(E33,I33) -> 44
A34: =LISTE!DV1 -> Travail manuel / Ecriture | B34: =IF(H4<>"",VLOOKUP(H4,LISTE!A3:EM72,126,FALSE),"") -> 14 | C34: =IF(H4<>"",VLOOKUP(H4,LISTE!A3:EM72,127,FALSE),"") -> 10 | D34: =IF(H4<>"",VLOOKUP(H4,LISTE!A3:EM72,128,FALSE),"") -> 0 | E34: =SUM(B34:D34) -> 24 | F34: =IF(H4<>"",VLOOKUP(H4,LISTE!A3:EM72,129,FALSE),"") -> 9 | G34: =IF(H4<>"",VLOOKUP(H4,LISTE!A3:EM72,130,FALSE),"") -> 11 | H34: =IF(H4<>"",VLOOKUP(H4,LISTE!A3:EM72,131,FALSE),"") -> 0 | I34: =SUM(F34:H34) -> 20 | J34: =SUM(E34,I34) -> 44
A35: MAXIMA | B35: 50 | C35: 50 | D35: 100 | E35: 200 | F35: 50 | G35: 50 | H35: 100 | I35: 200 | J35: 400
A36: =LISTE!EB1 -> Anglais | B36: =IF(H4<>"",VLOOKUP(H4,LISTE!A3:EM72,132,FALSE),"") -> 41 | C36: =IF(H4<>"",VLOOKUP(H4,LISTE!A3:EM72,133,FALSE),"") -> 36 | D36: =IF(H4<>"",VLOOKUP(H4,LISTE!A3:EM72,134,FALSE),"") -> 55 | E36: =SUM(B36:D36) -> 132 | F36: =IF(H4<>"",VLOOKUP(H4,LISTE!A3:EM72,135,FALSE),"") -> 37 | G36: =IF(H4<>"",VLOOKUP(H4,LISTE!A3:EM72,136,FALSE),"") -> 45 | H36: =IF(H4<>"",VLOOKUP(H4,LISTE!A3:EM72,137,FALSE),"") -> 32 | I36: =SUM(F36:H36) -> 114 | J36: =SUM(E36,I36) -> 246
A37: =LISTE!EH1 -> Français | B37: =IF(H4<>"",VLOOKUP(H4,LISTE!A3:EM72,138,FALSE),"") -> 21 | C37: =IF(H4<>"",VLOOKUP(H4,LISTE!A3:EM72,139,FALSE),"") -> 34 | D37: =IF(H4<>"",VLOOKUP(H4,LISTE!A3:EM72,140,FALSE),"") -> 52 | E37: =SUM(B37:D37) -> 107 | F37: =IF(H4<>"",VLOOKUP(H4,LISTE!A3:EM72,141,FALSE),"") -> 36 | G37: =IF(H4<>"",VLOOKUP(H4,LISTE!A3:EM72,142,FALSE),"") -> 30 | H37: =IF(H4<>"",VLOOKUP(H4,LISTE!A3:EM72,143,FALSE),"") -> 56 | I37: =SUM(F37:H37) -> 122 | J37: =SUM(E37,I37) -> 229
A38: MAXIMA GENERAUX | B38: =10*COUNTA(B13:B15)+20*COUNTA(B17:B27)+40*COUNTA(B29:B34)+50*COUNTA(B36:B37) -> 590 | C38: =10*COUNTA(C13:C15)+20*COUNTA(C17:C27)+40*COUNTA(C29:C34)+50*COUNTA(C36:C37) -> 590 | D38: =20*COUNTA(D13:D15)+40*COUNTA(D17:D27)+80*COUNTA(D29:D34)+100*COUNTA(D36:D37) -> 1180 | E38: =40*COUNTA(E13:E15)+80*COUNTA(E17:E27)+160*COUNTA(E29:E34)+200*COUNTA(E36:E37) -> 2360 | F38: =10*COUNTA(F13:F15)+20*COUNTA(F17:F27)+40*COUNTA(F29:F34)+50*COUNTA(F36:F37) -> 590 | G38: =10*COUNTA(G13:G15)+20*COUNTA(G17:G27)+40*COUNTA(G29:G34)+50*COUNTA(G36:G37) -> 590 | H38: =20*COUNTA(H13:H15)+40*COUNTA(H17:H27)+80*COUNTA(H29:H34)+100*COUNTA(H36:H37) -> 1180 | I38: =40*COUNTA(I13:I15)+80*COUNTA(I17:I27)+160*COUNTA(I29:I34)+200*COUNTA(I36:I37) -> 2360 | J38: =80*COUNTA(J13:J15)+160*COUNTA(J17:J27)+320*COUNTA(J29:J34)+400*COUNTA(J36:J37) -> 4720
A39: TOTAUX | B39: =SUM(B13:B15,B17:B27,B29:B34,B36:B37) -> 275 | C39: =SUM(C13:C15,C17:C27,C29:C34,C36:C37) -> 291 | D39: =SUM(D13:D15,D17:D27,D29:D34,D36:D37) -> 427 | E39: =SUM(E13:E15,E17:E27,E29:E34,E36:E37) -> 993 | F39: =SUM(F13:F15,F17:F27,F29:F34,F36:F37) -> 278 | G39: =SUM(G13:G15,G17:G27,G29:G34,G36:G37) -> 270 | H39: =SUM(H13:H15,H17:H27,H29:H34,H36:H37) -> 364 | I39: =SUM(I13:I15,I17:I27,I29:I34,I36:I37) -> 912 | J39: =SUM(J13:J15,J17:J27,J29:J34,J36:J37) -> 1905 | L39: - PASSE (1) - DOUBLE (1) LE……../……/ 20…... Le Chef d'Etablissement Sceau de l'école
A40: POURCETAGE | B40: =(B39/B38)*100 -> 46.610169 | C40: =(C39/C38)*100 -> 49.322034 | D40: =(D39/D38)*100 -> 36.186441 | E40: =(E39/E38)*100 -> 42.076271 | F40: =(F39/F38)*100 -> 47.118644 | G40: =(G39/G38)*100 -> 45.762712 | H40: =(H39/H38)*100 -> 30.847458 | I40: =(I39/I38)*100 -> 38.644068 | J40: =(J39/J38)*100 -> 40.360169
A41: PLACE / NBRE D'ELEVES | B41: =IF(H4<>"",VLOOKUP(H4,LISTE!A3:FE72,145,FALSE),"") -> 6e | C41: =IF(H4<>"",VLOOKUP(H4,LISTE!A3:FE72,147,FALSE),"") -> 6e | D41: =IF(H4<>"",VLOOKUP(H4,LISTE!A3:FE72,149,FALSE),"") -> 1e | E41: =IF(H4<>"",VLOOKUP(H4,LISTE!A3:FE72,151,FALSE),"") -> 2e | F41: =IF(H4<>"",VLOOKUP(H4,LISTE!A3:FE72,153,FALSE),"") -> 5e | G41: =IF(H4<>"",VLOOKUP(H4,LISTE!A3:FE72,155,FALSE),"") -> 8e | H41: =IF(H4<>"",VLOOKUP(H4,LISTE!A3:FE72,157,FALSE),"") -> 8e | I41: =IF(H4<>"",VLOOKUP(H4,LISTE!A3:FE72,159,FALSE),"") -> 7e | J41: =IF(H4<>"",VLOOKUP(H4,LISTE!A3:FE72,161,FALSE),"") -> 7e
...

Sheet LISTE
A1: NOMS | B1: N° ID | C1: SEXE | D1: DATE DE NAISS | E1: CLASSE | F1: N° PERM | G1: PROVINCE | H1: VILLE | I1: COMMUNE | J1: ECOLE | K1: CODE | L1: Religion | R1: Education à la vie | X1: Ed. Civ & Morale | AD1: Chimie | AJ1: Dessin | AP1: Education physique | AV1: Economie politique | BB1: Education music. /Théatrale | BH1: Geographie | BN1: Histoire | BT1: Informatique | BZ1: Langues nationales | CF1: Microbiologie | CL1: Physique | CR1: Didactiques des disciplines | CX1: Didactique générale | DD1: Mathématiques | DJ1: Pédagogie | DP1: Psychologie | DV1: Travail manuel / Ecriture | EB1: Anglais | EH1: Français | EN1: classement ou proclammation
L2: 1er | M2: 2èP | N2: EX | O2: 3èP | P2: 4èP | Q2: EX | R2: 1er | S2: 2èP | T2: EX | U2: 3èP | V2: 4èP | W2: EX | X2: 1er | Y2: 2èP | Z2: EX | AA2: 3èP | AB2: 4èP | AC2: EX | AD2: 1er | AE2: 2èP | AF2: EX | AG2: 3èP | AH2: 4èP | AI2: EX | AJ2: 1er | AK2: 2èP | AL2: EX | AM2: 3èP | AN2: 4èP | AO2: EX | AP2: 1er | AQ2: 2èP | AR2: EX | AS2: 3èP | AT2: 4èP | AU2: EX | AV2: 1er | AW2: 2èP | AX2: EX | AY2: 3èP | AZ2: 4èP | BA2: EX | BB2: 1er | BC2: 2èP | BD2: EX | BE2: 3èP | BF2: 4èP | BG2: EX | BH2: 1er | BI2: 2èP | BJ2: EX | BK2: 3èP | BL2: 4èP | BM2: EX | BN2: 1er | BO2: 2èP | BP2: EX | BQ2: 3èP | BR2: 4èP | BS2: EX | BT2: 1er | BU2: 2èP | BV2: EX | BW2: 3èP | BX2: 4èP | BY2: EX | BZ2: 1er | CA2: 2èP | CB2: EX | CC2: 3èP | CD2: 4èP | CE2: EX | CF2: 1er | CG2: 2èP | CH2: EX | CI2: 3èP | CJ2: 4èP | CK2: EX | CL2: 1er | CM2: 2èP | CN2: EX | CO2: 3èP | CP2: 4èP | CQ2: EX | CR2: 1er | CS2: 2èP | CT2: EX | CU2: 3èP | CV2: 4èP | CW2: EX | CX2: 1er | CY2: 2èP | CZ2: EX | DA2: 3èP | DB2: 4èP | DC2: EX | DD2: 1er | DE2: 2èP | DF2: EX | DG2: 3èP | DH2: 4èP | DI2: EX | DJ2: 1er | DK2: 2èP | DL2: EX | DM2: 3èP | DN2: 4èP | DO2: EX | DP2: 1er | DQ2: 2èP | DR2: EX | DS2: 3èP | DT2: 4èP | DU2: EX | DV2: 1er | DW2: 2èP | DX2: EX | DY2: 3èP | DZ2: 4èP | EA2: EX | EB2: 1er | EC2: 2èP | ED2: EX | EE2: 3èP | EF2: 4èP | EG2: EX | EH2: 1er | EI2: 2èP | EJ2: EX | EK2: 3èP | EL2: 4èP | EM2: EX | EN2: 1er P | EP2: 2eP | ER2: ex 1er S | ET2: TOT 1er S | EV2: 3e P | EX2: 4e P | EZ2: Ex 2è S | FB2: TOT 2e S | FD2: T.G
A3: KALALA MUSANGU Chris | B3: CO1111 | C3: M | D3: 39334 | E3: 2ème H.P | F3: PERM01 | G3: Haut-Katanga | H3: Lubumbashi | I3: Annexe | J3: C.S EXCEL | K3: 710001 | L3: 5 | M3: 5 | N3: 11 | O3: 5 | P3: 7 | Q3: 9 | R3: 3 | S3: 4 | T3: 11 | U3: 6 | V3: 3 | W3: 10 | X3: 3 | Y3: 3 | Z3: 11 | AA3: 5 | AB3: 5 | AC3: 10 | AD3: 3 | AE3: 3 | AF3: 11 | AG3: 5 | AH3: 5 | AI3: 11 | AJ3: 10 | AK3: 11 | AL3: 20 | AM3: 9 | AN3: 11 | AO3: 20 | AP3: 9 | AQ3: 9 | AR3: 22 | AS3: 10 | AT3: 12 | AU3: 30 | AV3: 9 | AW3: 9 | AX3: 22 | AY3: 10 | AZ3: 12 | BA3: 30 | BB3: 11 | BC3: 10 | BD3: 23 | BE3: 9 | BF3: 9 | BG3: 20 | BH3: 11 | BI3: 13 | BJ3: 22 | BK3: 11 | BL3: 11 | BM3: 11 | BN3: 11 | BO3: 9 | BP3: 22 | BQ3: 9 | BR3: 11 | BS3: 26 | BT3: 15 | BU3: 12 | BW3: 11 | BX3: 10 | BZ3: 11 | CA3: 9 | CB3: 22 | CC3: 9 | CD3: 11 | CE3: 26 | CF3: 11 | CG3: 9 | CH3: 22 | CI3: 9 | CJ3: 11 | CK3: 26 | CL3: 11 | CM3: 9 | CN3: 22 | CO3: 9 | CP3: 11 | CQ3: 26 | CR3: 11 | CS3: 12 | CU3: 9 | CV3: 9 | CX3: 9 | CY3: 9 | DA3: 9 | DB3: 10 | DD3: 21 | DE3: 18 | DF3: 45 | DG3: 18 | DH3: 18 | DI3: 55 | DJ3: 11 | DK3: 12 | DM3: 9 | DN3: 9 | DP3: 11 | DQ3: 12 | DS3: 9 | DT3: 9 | DV3: 11 | DW3: 12 | DY3: 9 | DZ3: 9 | EB3: 26 | EC3: 33 | ED3: 55 | EE3: 25 | EF3: 30 | EG3: 55 | EH3: 30 | EI3: 29 | EJ3: 54 | EK3: 33 | EL3: 23 | EM3: 56 | EN3: =SUM(L3,R3,X3,AD3,AJ3,AP3,AV3,BB3,BH3,BN3,BT3,BZ3,CF3,CL3,CR3,CX3,DD3,DJ3,DP3,DV3,EB3,EH3)/BULLETIN!$B$38*100 -> 42.881356 | EO3: =RANK(EN3,$EN$3:$EN$72)&"e" -> 9e | EP3: =SUM(M3,S3,Y3,AE3,AK3,AQ3,AW3,BC3,BI3,BO3,BU3,CA3,CG3,CS3,CY3,DE3,DK3,DQ3,EC3,EI3,CM3,DW3)/BULLETIN!$C$38*100 -> 42.711864 | EQ3: =RANK(EP3,$EP$3:$EP$72)&"e" -> 9e | ER3: =SUM(N3,T3,Z3,AF3,AL3,AR3,AX3,BD3,BJ3,BP3,BV3,CB3,CH3,CT3,CZ3,DF3,DL3,DR3,ED3,EJ3,CN3,DX3)/BULLETIN!$D$38*100 -> 33.474576 | ES3: =RANK(ER3,$ER$3:$ER$72)&"e" -> 3e | ET3: =SUM(L3:N3,R3:T3,X3:Z3,AD3:AF3,AJ3:AL3,AP3:AR3,AV3:AX3,BB3:BD3,BH3:BJ3,BN3:BP3,BT3:BV3,BZ3:CB3,CF3:CH3,CR3:CT3,CX3:CZ3,DD3:DF3,DJ3:DL3,DP3:DR3,EB3:ED3,EH3:EJ3,CL3:CN3,DV3:DX3)/BULLETIN!$E$38*100 -> 38.135593 | EU3: =RANK(ET3,$ET$3:$ET$72)&"e" -> 9e | EV3: =SUM(O3,U3,AA3,AG3,AM3,AS3,AY3,BE3,BK3,BQ3,BW3,CC3,CI3,CU3,DA3,DG3,DM3,DS3,EE3,EK3,CO3,DY3)/BULLETIN!$F$38*100 -> 40.338983 | EW3: =RANK(EV3,$EV$3:$EV$72)&"e" -> 9e | EX3: =SUM(P3,V3,AB3,AH3,AN3,AT3,AZ3,BF3,BL3,BR3,BX3,CD3,CJ3,CV3,DB3,DH3,DN3,DS3,EF3,EL3,CP3,DZ3)/BULLETIN!$G$38*100 -> 41.694915 | EY3: =RANK(EX3,$EX$3:$EX$72)&"e" -> 9e | EZ3: =SUM(Q3,W3,AC3,AI3,AO3,AU3,BA3,BG3,BM3,BS3,BY3,CE3,CK3,CW3,DC3,DI3,DO3,DU3,EG3,EM3,EA3,CQ3)/BULLETIN!$H$38*100 -> 35.677966 | FA3: =RANK(EZ3,$EZ$3:$EZ$72)&"e" -> 1e | FB3: =SUM(O3:Q3,U3:W3,AA3:AC3,AG3:AI3,AM3:AO3,AS3:AU3,AY3:BA3,BE3:BG3,BK3:BM3,BQ3:BS3,BW3:BY3,CC3:CE3,CI3:CK3,CU3:CW3,DA3:DC3,DM3:DO3,DS3:DU3,EE3:EG3,EK3:EM3,DG3:DI3,CO3:CQ3,DY3:EA3)/BULLETIN!$I$38*100 -> 38.347458 | FC3: =RANK(FB3,$FB$3:$FB$72)&"e" -> 9e | FD3: =SUM(L3:EM3)/BULLETIN!$J$38*100 -> 38.241525 | FE3: =RANK(FD3,$FD$3:$FD$72)&"e" -> 9e
A4: KASONGO MWANZA Marcel | B4: CO1112 | C4: M | D4: 39854 | E4: 2ème H.P | F4: PERM02 | G4: Lualaba | H4: Lubumbashi | I4: Ruashi | J4: C.S EXCEL | K4: 710002 | L4: 3 | M4: 2 | N4: 12 | O4: 8 | P4: 6 | Q4: 10 | R4: 6 | S4: 5 | T4: 11 | U4: 3 | V4: 9 | W4: 11 | X4: 5 | Y4: 8 | Z4: 13 | AA4: 6 | AB4: 7 | AC4: 11 | AD4: 5 | AE4: 8 | AF4: 13 | AG4: 6 | AH4: 7 | AI4: 11 | AJ4: 9 | AK4: 10 | AL4: 20 | AM4: 11 | AN4: 14 | AO4: 21 | AP4: 12 | AQ4: 12 | AR4: 22 | AS4: 10 | AT4: 9 | AU4: 29 | AV4: 12 | AW4: 12 | AX4: 22 | AY4: 10 | AZ4: 9 | BA4: 29 | BB4: 13 | BC4: 14 | BD4: 23 | BE4: 11 | BF4: 11 | BG4: 22 | BH4: 10 | BI4: 15 | BJ4: 22 | BK4: 12 | BL4: 12 | BM4: 11 | BN4: 13 | BO4: 15 | BP4: 21 | BQ4: 10 | BR4: 12 | BS4: 22 | BT4: 10 | BU4: 11 | BW4: 11 | BX4: 11 | BZ4: 13 | CA4: 15 | CB4: 21 | CC4: 10 | CD4: 12 | CE4: 22 | CF4: 13 | CG4: 15 | CH4: 21 | CI4: 10 | CJ4: 12 | CK4: 22 | CL4: 13 | CM4: 15 | CN4: 21 | CO4: 10 | CP4: 12 | CQ4: 22 | CR4: 13 | CS4: 17 | CU4: 12 | CV4: 11 | CX4: 10 | CY4: 11 | DA4: 15 | DB4: 16 | DD4: 18 | DE4: 21 | DF4: 34 | DG4: 18 | DH4: 18 | DI4: 45 | DJ4: 13 | DK4: 17 | DM4: 12 | DN4: 11 | DP4: 13 | DQ4: 17 | DS4: 12 | DT4: 11 | DV4: 13 | DW4: 17 | DY4: 12 | DZ4: 11 | EB4: 30 | EC4: 29 | ED4: 56 | EE4: 32 | EF4: 33 | EG4: 60 | EH4: 34 | EI4: 36 | EJ4: 55 | EK4: 25 | EL4: 25 | EM4: 59 | EN4: =SUM(L4,R4,X4,AD4,AJ4,AP4,AV4,BB4,BH4,BN4,BT4,BZ4,CF4,CL4,CR4,CX4,DD4,DJ4,DP4,DV4,EB4,EH4)/BULLETIN!$B$38*100 -> 47.627119 | EO4: =RANK(EN4,$EN$3:$EN$72)&"e" -> 3e | EP4: =SUM(M4,S4,Y4,AE4,AK4,AQ4,AW4,BC4,BI4,BO4,BU4,CA4,CG4,CS4,CY4,DE4,DK4,DQ4,EC4,EI4,CM4,DW4)/BULLETIN!$C$38*100 -> 54.576271 | EQ4: =RANK(EP4,$EP$3:$EP$72)&"e" -> 2e | ER4: =SUM(N4,T4,Z4,AF4,AL4,AR4,AX4,BD4,BJ4,BP4,BV4,CB4,CH4,CT4,CZ4,DF4,DL4,DR4,ED4,EJ4,CN4,DX4)/BULLETIN!$D$38*100 -> 32.79661 | ES4: =RANK(ER4,$ER$3:$ER$72)&"e" -> 8e | ET4: =SUM(L4:N4,R4:T4,X4:Z4,AD4:AF4,AJ4:AL4,AP4:AR4,AV4:AX4,BB4:BD4,BH4:BJ4,BN4:BP4,BT4:BV4,BZ4:CB4,CF4:CH4,CR4:CT4,CX4:CZ4,DD4:DF4,DJ4:DL4,DP4:DR4,EB4:ED4,EH4:EJ4,CL4:CN4,DV4:DX4)/BULLETIN!$E$38*100 -> 41.949153 | EU4: =RANK(ET4,$ET$3:$ET$72)&"e" -> 3e | EV4: =SUM(O4,U4,AA4,AG4,AM4,AS4,AY4,BE4,BK4,BQ4,BW4,CC4,CI4,CU4,DA4,DG4,DM4,DS4,EE4,EK4,CO4,DY4)/BULLETIN!$F$38*100 -> 45.084746 | EW4: =RANK(EV4,$EV$3:$EV$72)&"e" -> 7e | EX4: =SUM(P4,V4,AB4,AH4,AN4,AT4,AZ4,BF4,BL4,BR4,BX4,CD4,CJ4,CV4,DB4,DH4,DN4,DS4,EF4,EL4,CP4,DZ4)/BULLETIN!$G$38*100 -> 47.457627 | EY4: =RANK(EX4,$EX$3:$EX$72)&"e" -> 5e | EZ4: =SUM(Q4,W4,AC4,AI4,AO4,AU4,BA4,BG4,BM4,BS4,BY4,CE4,CK4,CW4,DC4,DI4,DO4,DU4,EG4,EM4,EA4,CQ4)/BULLETIN!$H$38*100 -> 34.491525 | FA4: =RANK(EZ4,$EZ$3:$EZ$72)&"e" -> 3e | FB4: =SUM(O4:Q4,U4:W4,AA4:AC4,AG4:AI4,AM4:AO4,AS4:AU4,AY4:BA4,BE4:BG4,BK4:BM4,BQ4:BS4,BW4:BY4,CC4:CE4,CI4:CK4,CU4:CW4,DA4:DC4,DM4:DO4,DS4:DU4,EE4:EG4,EK4:EM4,DG4:DI4,CO4:CQ4,DY4:EA4)/BULLETIN!$I$38*100 -> 40.338983 | FC4: =RANK(FB4,$FB$3:$FB$72)&"e" -> 6e | FD4: =SUM(L4:EM4)/BULLETIN!$J$38*100 -> 41.144068 | FE4: =RANK(FD4,$FD$3:$FD$72)&"e" -> 3e
A5: MASENGO MUKENDI Rachel | B5: CO1113 | C5: F | D5: 39541 | E5: 2ème H.P | F5: PERM03 | G5: Haut-Lomami | H5: Lubumbashi | I5: Kampemba | J5: C.S EXCEL | K5: 710003 | L5: 5 | M5: 4 | N5: 11 | O5: 6 | P5: 3 | Q5: 11 | R5: 3 | S5: 4 | T5: 10 | U5: 5 | V5: 6 | W5: 9 | X5: 6 | Y5: 6 | Z5: 12 | AA5: 6 | AB5: 7 | AC5: 10 | AD5: 6 | AE5: 6 | AF5: 12 | AG5: 6 | AH5: 7 | AI5: 15 | AJ5: 10 | AK5: 12 | AL5: 20 | AM5: 11 | AN5: 11 | AO5: 22 | AP5: 15 | AQ5: 15 | AR5: 23 | AS5: 15 | AT5: 11 | AU5: 25 | AV5: 15 | AW5: 15 | AX5: 23 | AY5: 15 | AZ5: 11 | BA5: 25 | BB5: 11 | BC5: 12 | BD5: 24 | BE5: 17 | BF5: 12 | BG5: 21 | BH5: 11 | BI5: 13 | BJ5: 22 | BK5: 12 | BL5: 9 | BM5: 11 | BN5: 9 | BO5: 11 | BP5: 20 | BQ5: 18 | BR5: 11 | BS5: 21 | BT5: 13 | BU5: 15 | BW5: 17 | BX5: 12 | BZ5: 9 | CA5: 11 | CB5: 20 | CC5: 18 | CD5: 11 | CE5: 21 | CF5: 9 | CG5: 11 | CH5: 20 | CI5: 18 | CJ5: 11 | CK5: 21 | CL5: 9 | CM5: 11 | CN5: 20 | CO5: 18 | CP5: 11 | CQ5: 21 | CR5: 11 | CS5: 11 | CU5: 10 | CV5: 9 | CX5: 9 | CY5: 9 | DA5: 11 | DB5: 11 | DD5: 21 | DE5: 18 | DF5: 40 | DG5: 20 | DH5: 21 | DI5: 44 | DJ5: 11 | DK5: 11 | DM5: 10 | DN5: 9 | DP5: 11 | DQ5: 11 | DS5: 10 | DT5: 9 | DV5: 11 | DW5: 11 | DY5: 10 | DZ5: 9 | EB5: 35 | EC5: 23 | ED5: 54 | EE5: 37 | EF5: 43 | EG5: 49 | EH5: 39 | EI5: 41 | EJ5: 53 | EK5: 40 | EL5: 32 | EM5: 57 | EN5: =SUM(L5,R5,X5,AD5,AJ5,AP5,AV5,BB5,BH5,BN5,BT5,BZ5,CF5,CL5,CR5,CX5,DD5,DJ5,DP5,DV5,EB5,EH5)/BULLETIN!$B$38*100 -> 47.288136 | EO5: =RANK(EN5,$EN$3:$EN$72)&"e" -> 4e | EP5: =SUM(M5,S5,Y5,AE5,AK5,AQ5,AW5,BC5,BI5,BO5,BU5,CA5,CG5,CS5,CY5,DE5,DK5,DQ5,EC5,EI5,CM5,DW5)/BULLETIN!$C$38*100 -> 47.627119 | EQ5: =RANK(EP5,$EP$3:$EP$72)&"e" -> 8e | ER5: =SUM(N5,T5,Z5,AF5,AL5,AR5,AX5,BD5,BJ5,BP5,BV5,CB5,CH5,CT5,CZ5,DF5,DL5,DR5,ED5,EJ5,CN5,DX5)/BULLETIN!$D$38*100 -> 32.542373 | ES5: =RANK(ER5,$ER$3:$ER$72)&"e" -> 9e | ET5: =SUM(L5:N5,R5:T5,X5:Z5,AD5:AF5,AJ5:AL5,AP5:AR5,AV5:AX5,BB5:BD5,BH5:BJ5,BN5:BP5,BT5:BV5,BZ5:CB5,CF5:CH5,CR5:CT5,CX5:CZ5,DD5:DF5,DJ5:DL5,DP5:DR5,EB5:ED5,EH5:EJ5,CL5:CN5,DV5:DX5)/BULLETIN!$E$38*100 -> 40 | EU5: =RANK(ET5,$ET$3:$ET$72)&"e" -> 7e | EV5: =SUM(O5,U5,AA5,AG5,AM5,AS5,AY5,BE5,BK5,BQ5,BW5,CC5,CI5,CU5,DA5,DG5,DM5,DS5,EE5,EK5,CO5,DY5)/BULLETIN!$F$38*100 -> 55.932203 | EW5: =RANK(EV5,$EV$3:$EV$72)&"e" -> 1e | EX5: =SUM(P5,V5,AB5,AH5,AN5,AT5,AZ5,BF5,BL5,BR5,BX5,CD5,CJ5,CV5,DB5,DH5,DN5,DS5,EF5,EL5,CP5,DZ5)/BULLETIN!$G$38*100 -> 46.949153 | EY5: =RANK(EX5,$EX$3:$EX$72)&"e" -> 7e | EZ5: =SUM(Q5,W5,AC5,AI5,AO5,AU5,BA5,BG5,BM5,BS5,BY5,CE5,CK5,CW5,DC5,DI5,DO5,DU5,EG5,EM5,EA5,CQ5)/BULLETIN!$H$38*100 -> 32.457627 | FA5: =RANK(EZ5,$EZ$3:$EZ$72)&"e" -> 7e | FB5: =SUM(O5:Q5,U5:W5,AA5:AC5,AG5:AI5,AM5:AO5,AS5:AU5,AY5:BA5,BE5:BG5,BK5:BM5,BQ5:BS5,BW5:BY5,CC5:CE5,CI5:CK5,CU5:CW5,DA5:DC5,DM5:DO5,DS5:DU5,EE5:EG5,EK5:EM5,DG5:DI5,CO5:CQ5,DY5:EA5)/BULLETIN!$I$38*100 -> 41.90678 | FC5: =RANK(FB5,$FB$3:$FB$72)&"e" -> 2e | FD5: =SUM(L5:EM5)/BULLETIN!$J$38*100 -> 40.95339 | FE5: =RANK(FD5,$FD$3:$FD$72)&"e" -> 4e
A6: KALABA KAMBA Chadrack | B6: CO1114 | C6: M | D6: 40529 | E6: 2ème H.P | F6: PERM04 | G6: Equateur | H6: Lubumbashi | I6: Kamalondo | J6: C.S EXCEL | K6: 710004 | L6: 5 | M6: 7 | N6: 10 | O6: 8 | P6: 5 | Q6: 10 | R6: 5 | S6: 7 | T6: 12 | U6: 6 | V6: 7 | W6: 9 | X6: 5 | Y6: 8 | Z6: 11 | AA6: 6 | AB6: 4 | AC6: 9 | AD6: 5 | AE6: 8 | AF6: 11 | AG6: 6 | AH6: 4 | AI6: 11 | AJ6: 9 | AK6: 17 | AL6: 22 | AM6: 9 | AN6: 10 | AO6: 21 | AP6: 11 | AQ6: 11 | AR6: 24 | AS6: 12 | AT6: 10 | AU6: 21 | AV6: 11 | AW6: 11 | AX6: 24 | AY6: 12 | AZ6: 10 | BA6: 21 | BB6: 9 | BC6: 10 | BD6: 24 | BE6: 10 | BF6: 11 | BG6: 22 | BH6: 9 | BI6: 10 | BJ6: 21 | BK6: 11 | BL6: 12 | BM6: 16 | BN6: 11 | BO6: 11 | BP6: 29 | BQ6: 12 | BR6: 9 | BS6: 24 | BT6: 11 | BU6: 13 | BW6: 9 | BX6: 12 | BZ6: 11 | CA6: 11 | CB6: 29 | CC6: 12 | CD6: 9 | CE6: 24 | CF6: 11 | CG6: 11 | CH6: 29 | CI6: 12 | CJ6: 9 | CK6: 24 | CL6: 11 | CM6: 11 | CN6: 29 | CO6: 12 | CP6: 9 | CQ6: 24 | CR6: 14 | CS6: 10 | CU6: 9 | CV6: 11 | CX6: 11 | CY6: 15 | DA6: 11 | DB6: 9 | DD6: 22 | DE6: 20 | DF6: 45 | DG6: 21 | DH6: 21 | DI6: 40 | DJ6: 14 | DK6: 10 | DM6: 9 | DN6: 11 | DP6: 14 | DQ6: 10 | DS6: 9 | DT6: 11 | DV6: 14 | DW6: 10 | DY6: 9 | DZ6: 11 | EB6: 41 | EC6: 36 | ED6: 55 | EE6: 37 | EF6: 45 | EG6: 32 | EH6: 21 | EI6: 34 | EJ6: 52 | EK6: 36 | EL6: 30 | EM6: 56 | EN6: =SUM(L6,R6,X6,AD6,AJ6,AP6,AV6,BB6,BH6,BN6,BT6,BZ6,CF6,CL6,CR6,CX6,DD6,DJ6,DP6,DV6,EB6,EH6)/BULLETIN!$B$38*100 -> 46.610169 | EO6: =RANK(EN6,$EN$3:$EN$72)&"e" -> 6e | EP6: =SUM(M6,S6,Y6,AE6,AK6,AQ6,AW6,BC6,BI6,BO6,BU6,CA6,CG6,CS6,CY6,DE6,DK6,DQ6,EC6,EI6,CM6,DW6)/BULLETIN!$C$38*100 -> 49.322034 | EQ6: =RANK(EP6,$EP$3:$EP$72)&"e" -> 6e | ER6: =SUM(N6,T6,Z6,AF6,AL6,AR6,AX6,BD6,BJ6,BP6,BV6,CB6,CH6,CT6,CZ6,DF6,DL6,DR6,ED6,EJ6,CN6,DX6)/BULLETIN!$D$38*100 -> 36.186441 | ES6: =RANK(ER6,$ER$3:$ER$72)&"e" -> 1e | ET6: =SUM(L6:N6,R6:T6,X6:Z6,AD6:AF6,AJ6:AL6,AP6:AR6,AV6:AX6,BB6:BD6,BH6:BJ6,BN6:BP6,BT6:BV6,BZ6:CB6,CF6:CH6,CR6:CT6,CX6:CZ6,DD6:DF6,DJ6:DL6,DP6:DR6,EB6:ED6,EH6:EJ6,CL6:CN6,DV6:DX6)/BULLETIN!$E$38*100 -> 42.076271 | EU6: =RANK(ET6,$ET$3:$ET$72)&"e" -> 2e | EV6: =SUM(O6,U6,AA6,AG6,AM6,AS6,AY6,BE6,BK6,BQ6,BW6,CC6,CI6,CU6,DA6,DG6,DM6,DS6,EE6,EK6,CO6,DY6)/BULLETIN!$F$38*100 -> 47.118644 | EW6: =RANK(EV6,$EV$3:$EV$72)&"e" -> 5e | EX6: =SUM(P6,V6,AB6,AH6,AN6,AT6,AZ6,BF6,BL6,BR6,BX6,CD6,CJ6,CV6,DB6,DH6,DN6,DS6,EF6,EL6,CP6,DZ6)/BULLETIN!$G$38*100 -> 45.423729 | EY6: =RANK(EX6,$EX$3:$EX$72)&"e" -> 8e | EZ6: =SUM(Q6,W6,AC6,AI6,AO6,AU6,BA6,BG6,BM6,BS6,BY6,CE6,CK6,CW6,DC6,DI6,DO6,DU6,EG6,EM6,EA6,CQ6)/BULLETIN!$H$38*100 -> 30.847458 | FA6: =RANK(EZ6,$EZ$3:$EZ$72)&"e" -> 8e | FB6: =SUM(O6:Q6,U6:W6,AA6:AC6,AG6:AI6,AM6:AO6,AS6:AU6,AY6:BA6,BE6:BG6,BK6:BM6,BQ6:BS6,BW6:BY6,CC6:CE6,CI6:CK6,CU6:CW6,DA6:DC6,DM6:DO6,DS6:DU6,EE6:EG6,EK6:EM6,DG6:DI6,CO6:CQ6,DY6:EA6)/BULLETIN!$I$38*100 -> 38.644068 | FC6: =RANK(FB6,$FB$3:$FB$72)&"e" -> 7e | FD6: =SUM(L6:EM6)/BULLETIN!$J$38*100 -> 40.360169 | FE6: =RANK(FD6,$FD$3:$FD$72)&"e" -> 7e
A7: MULANGA MUSWAMBA Ane | B7: CO1115 | C7: F | D7: 39232 | E7: 2ème H.P | F7: PERM05 | G7: Tanganika | H7: Lubumbashi | I7: Katuba | J7: C.S EXCEL | K7: 710005 | L7: 7 | M7: 5 | N7: 9 | O7: 8 | P7: 5 | Q7: 12 | R7: 6 | S7: 5 | T7: 12 | U7: 9 | V7: 4 | W7: 10 | X7: 6 | Y7: 5 | Z7: 11 | AA7: 5 | AB7: 7 | AC7: 11 | AD7: 6 | AE7: 5 | AF7: 11 | AG7: 5 | AH7: 7 | AI7: 11 | AJ7: 11 | AK7: 15 | AL7: 19 | AM7: 9 | AN7: 11 | AO7: 23 | AP7: 10 | AQ7: 9 | AR7: 21 | AS7: 11 | AT7: 11 | AU7: 20 | AV7: 10 | AW7: 9 | AX7: 21 | AY7: 11 | AZ7: 11 | BA7: 20 | BB7: 12 | BC7: 11 | BD7: 21 | BE7: 11 | BF7: 10 | BG7: 20 | BH7: 12 | BI7: 12 | BJ7: 20 | BK7: 13 | BL7: 12 | BM7: 10 | BN7: 17 | BO7: 17 | BP7: 22 | BQ7: 11 | BR7: 19 | BS7: 24 | BT7: 11 | BU7: 15 | BW7: 11 | BX7: 10 | BZ7: 17 | CA7: 17 | CB7: 22 | CC7: 11 | CD7: 19 | CE7: 24 | CF7: 17 | CG7: 17 | CH7: 22 | CI7: 11 | CJ7: 19 | CK7: 24 | CL7: 17 | CM7: 17 | CN7: 22 | CO7: 11 | CP7: 19 | CQ7: 24 | CR7: 11 | CS7: 15 | CU7: 14 | CV7: 11 | CX7: 11 | CY7: 16 | DA7: 12 | DB7: 11 | DD7: 24 | DE7: 21 | DF7: 43 | DG7: 21 | DH7: 32 | DI7: 45 | DJ7: 11 | DK7: 15 | DM7: 14 | DN7: 11 | DP7: 11 | DQ7: 15 | DS7: 14 | DT7: 11 | DV7: 11 | DW7: 15 | DY7: 14 | DZ7: 11 | EB7: 34 | EC7: 32 | ED7: 57 | EE7: 21 | EF7: 23 | EG7: 65 | EH7: 27 | EI7: 43 | EJ7: 55 | EK7: 39 | EL7: 32 | EM7: 54 | EN7: =SUM(L7,R7,X7,AD7,AJ7,AP7,AV7,BB7,BH7,BN7,BT7,BZ7,CF7,CL7,CR7,CX7,DD7,DJ7,DP7,DV7,EB7,EH7)/BULLETIN!$B$38*100 -> 50.677966 | EO7: =RANK(EN7,$EN$3:$EN$72)&"e" -> 1e | EP7: =SUM(M7,S7,Y7,AE7,AK7,AQ7,AW7,BC7,BI7,BO7,BU7,CA7,CG7,CS7,CY7,DE7,DK7,DQ7,EC7,EI7,CM7,DW7)/BULLETIN!$C$38*100 -> 56.101695 | EQ7: =RANK(EP7,$EP$3:$EP$72)&"e" -> 1e | ER7: =SUM(N7,T7,Z7,AF7,AL7,AR7,AX7,BD7,BJ7,BP7,BV7,CB7,CH7,CT7,CZ7,DF7,DL7,DR7,ED7,EJ7,CN7,DX7)/BULLETIN!$D$38*100 -> 32.881356 | ES7: =RANK(ER7,$ER$3:$ER$72)&"e" -> 7e | ET7: =SUM(L7:N7,R7:T7,X7:Z7,AD7:AF7,AJ7:AL7,AP7:AR7,AV7:AX7,BB7:BD7,BH7:BJ7,BN7:BP7,BT7:BV7,BZ7:CB7,CF7:CH7,CR7:CT7,CX7:CZ7,DD7:DF7,DJ7:DL7,DP7:DR7,EB7:ED7,EH7:EJ7,CL7:CN7,DV7:DX7)/BULLETIN!$E$38*100 -> 43.135593 | EU7: =RANK(ET7,$ET$3:$ET$72)&"e" -> 1e | EV7: =SUM(O7,U7,AA7,AG7,AM7,AS7,AY7,BE7,BK7,BQ7,BW7,CC7,CI7,CU7,DA7,DG7,DM7,DS7,EE7,EK7,CO7,DY7)/BULLETIN!$F$38*100 -> 48.474576 | EW7: =RANK(EV7,$EV$3:$EV$72)&"e" -> 3e | EX7: =SUM(P7,V7,AB7,AH7,AN7,AT7,AZ7,BF7,BL7,BR7,BX7,CD7,CJ7,CV7,DB7,DH7,DN7,DS7,EF7,EL7,CP7,DZ7)/BULLETIN!$G$38*100 -> 52.372881 | EY7: =RANK(EX7,$EX$3:$EX$72)&"e" -> 1e | EZ7: =SUM(Q7,W7,AC7,AI7,AO7,AU7,BA7,BG7,BM7,BS7,BY7,CE7,CK7,CW7,DC7,DI7,DO7,DU7,EG7,EM7,EA7,CQ7)/BULLETIN!$H$38*100 -> 33.644068 | FA7: =RANK(EZ7,$EZ$3:$EZ$72)&"e" -> 4e | FB7: =SUM(O7:Q7,U7:W7,AA7:AC7,AG7:AI7,AM7:AO7,AS7:AU7,AY7:BA7,BE7:BG7,BK7:BM7,BQ7:BS7,BW7:BY7,CC7:CE7,CI7:CK7,CU7:CW7,DA7:DC7,DM7:DO7,DS7:DU7,EE7:EG7,EK7:EM7,DG7:DI7,CO7:CQ7,DY7:EA7)/BULLETIN!$I$38*100 -> 41.90678 | FC7: =RANK(FB7,$FB$3:$FB$72)&"e" -> 2e | FD7: =SUM(L7:EM7)/BULLETIN!$J$38*100 -> 42.521186 | FE7: =RANK(FD7,$FD$3:$FD$72)&"e" -> 1e
A8: MWAMBA BUKASA Jethro | B8: CO1116 | C8: M | D8: 39732 | E8: 2ème H.P | F8: PERM06 | G8: Haut-Katanga | H8: Lubumbashi | I8: Annexe | J8: C.S EXCEL | K8: 710006 | L8: 6 | M8: 9 | N8: 14 | O8: 5 | P8: 7 | Q8: 11 | R8: 7 | S8: 7 | T8: 11 | U8: 5 | V8: 6 | W8: 11 | X8: 5 | Y8: 6 | Z8: 11 | AA8: 4 | AB8: 6 | AC8: 13 | AD8: 5 | AE8: 6 | AF8: 11 | AG8: 4 | AH8: 6 | AI8: 10 | AJ8: 11 | AK8: 14 | AL8: 21 | AM8: 11 | AN8: 19 | AO8: 21 | AP8: 11 | AQ8: 14 | AR8: 21 | AS8: 13 | AT8: 9 | AU8: 20 | AV8: 11 | AW8: 14 | AX8: 21 | AY8: 13 | AZ8: 9 | BA8: 20 | BB8: 17 | BC8: 11 | BD8: 21 | BE8: 11 | BF8: 16 | BG8: 21 | BH8: 10 | BI8: 11 | BJ8: 29 | BK8: 14 | BL8: 13 | BM8: 10 | BN8: 11 | BO8: 12 | BP8: 22 | BQ8: 16 | BR8: 9 | BS8: 25 | BT8: 10 | BU8: 11 | BW8: 11 | BX8: 12 | BZ8: 11 | CA8: 12 | CB8: 22 | CC8: 16 | CD8: 9 | CE8: 25 | CF8: 11 | CG8: 12 | CH8: 22 | CI8: 16 | CJ8: 9 | CK8: 25 | CL8: 11 | CM8: 12 | CN8: 22 | CO8: 16 | CP8: 9 | CQ8: 25 | CR8: 11 | CS8: 16 | CU8: 11 | CV8: 15 | CX8: 11 | CY8: 11 | DA8: 12 | DB8: 14 | DD8: 21 | DE8: 20 | DF8: 41 | DG8: 13 | DH8: 24 | DI8: 47 | DJ8: 11 | DK8: 16 | DM8: 11 | DN8: 15 | DP8: 11 | DQ8: 16 | DS8: 11 | DT8: 15 | DV8: 11 | DW8: 16 | DY8: 11 | DZ8: 15 | EB8: 25 | EC8: 27 | ED8: 50 | EE8: 20 | EF8: 25 | EG8: 45 | EH8: 25 | EI8: 32 | EJ8: 50 | EK8: 32 | EL8: 29 | EM8: 57 | EN8: =SUM(L8,R8,X8,AD8,AJ8,AP8,AV8,BB8,BH8,BN8,BT8,BZ8,CF8,CL8,CR8,CX8,DD8,DJ8,DP8,DV8,EB8,EH8)/BULLETIN!$B$38*100 -> 44.576271 | EO8: =RANK(EN8,$EN$3:$EN$72)&"e" -> 7e | EP8: =SUM(M8,S8,Y8,AE8,AK8,AQ8,AW8,BC8,BI8,BO8,BU8,CA8,CG8,CS8,CY8,DE8,DK8,DQ8,EC8,EI8,CM8,DW8)/BULLETIN!$C$38*100 -> 51.694915 | EQ8: =RANK(EP8,$EP$3:$EP$72)&"e" -> 4e | ER8: =SUM(N8,T8,Z8,AF8,AL8,AR8,AX8,BD8,BJ8,BP8,BV8,CB8,CH8,CT8,CZ8,DF8,DL8,DR8,ED8,EJ8,CN8,DX8)/BULLETIN!$D$38*100 -> 32.966102 | ES8: =RANK(ER8,$ER$3:$ER$72)&"e" -> 6e | ET8: =SUM(L8:N8,R8:T8,X8:Z8,AD8:AF8,AJ8:AL8,AP8:AR8,AV8:AX8,BB8:BD8,BH8:BJ8,BN8:BP8,BT8:BV8,BZ8:CB8,CF8:CH8,CR8:CT8,CX8:CZ8,DD8:DF8,DJ8:DL8,DP8:DR8,EB8:ED8,EH8:EJ8,CL8:CN8,DV8:DX8)/BULLETIN!$E$38*100 -> 40.550847 | EU8: =RANK(ET8,$ET$3:$ET$72)&"e" -> 6e | EV8: =SUM(O8,U8,AA8,AG8,AM8,AS8,AY8,BE8,BK8,BQ8,BW8,CC8,CI8,CU8,DA8,DG8,DM8,DS8,EE8,EK8,CO8,DY8)/BULLETIN!$F$38*100 -> 46.779661 | EW8: =RANK(EV8,$EV$3:$EV$72)&"e" -> 6e | EX8: =SUM(P8,V8,AB8,AH8,AN8,AT8,AZ8,BF8,BL8,BR8,BX8,CD8,CJ8,CV8,DB8,DH8,DN8,DS8,EF8,EL8,CP8,DZ8)/BULLETIN!$G$38*100 -> 48.644068 | EY8: =RANK(EX8,$EX$3:$EX$72)&"e" -> 3e | EZ8: =SUM(Q8,W8,AC8,AI8,AO8,AU8,BA8,BG8,BM8,BS8,BY8,CE8,CK8,CW8,DC8,DI8,DO8,DU8,EG8,EM8,EA8,CQ8)/BULLETIN!$H$38*100 -> 32.711864 | FA8: =RANK(EZ8,$EZ$3:$EZ$72)&"e" -> 5e | FB8: =SUM(O8:Q8,U8:W8,AA8:AC8,AG8:AI8,AM8:AO8,AS8:AU8,AY8:BA8,BE8:BG8,BK8:BM8,BQ8:BS8,BW8:BY8,CC8:CE8,CI8:CK8,CU8:CW8,DA8:DC8,DM8:DO8,DS8:DU8,EE8:EG8,EK8:EM8,DG8:DI8,CO8:CQ8,DY8:EA8)/BULLETIN!$I$38*100 -> 40.381356 | FC8: =RANK(FB8,$FB$3:$FB$72)&"e" -> 4e | FD8: =SUM(L8:EM8)/BULLETIN!$J$38*100 -> 40.466102 | FE8: =RANK(FD8,$FD$3:$FD$72)&"e" -> 6e
A9: MALABAR KASONGO Ruth | B9: CO1117 | C9: F | D9: 40007 | E9: 2ème H.P | F9: PERM07 | G9: Haut-Katanga | H9: Lubumbashi | I9: Lubumbashi | J9: C.S EXCEL | K9: 710007 | L9: 5 | M9: 7 | N9: 11 | O9: 6 | P9: 8 | Q9: 11 | R9: 8 | S9: 6 | T9: 10 | U9: 5 | V9: 9 | W9: 12 | X9: 4 | Y9: 7 | Z9: 10 | AA9: 4 | AB9: 6 | AC9: 11 | AD9: 4 | AE9: 7 | AF9: 10 | AG9: 4 | AH9: 6 | AI9: 9 | AJ9: 9 | AK9: 9 | AL9: 23 | AM9: 11 | AN9: 17 | AO9: 20 | AP9: 11 | AQ9: 15 | AR9: 20 | AS9: 16 | AT9: 11 | AU9: 22 | AV9: 11 | AW9: 15 | AX9: 20 | AY9: 16 | AZ9: 11 | BA9: 22 | BB9: 11 | BC9: 12 | BD9: 20 | BE9: 9 | BF9: 14 | BG9: 21 | BH9: 10 | BI9: 11 | BJ9: 28 | BK9: 11 | BL9: 12 | BM9: 10 | BN9: 16 | BO9: 14 | BP9: 22 | BQ9: 15 | BR9: 11 | BS9: 29 | BT9: 17 | BU9: 9 | BW9: 11 | BX9: 9 | BZ9: 16 | CA9: 14 | CB9: 22 | CC9: 15 | CD9: 11 | CE9: 29 | CF9: 16 | CG9: 14 | CH9: 22 | CI9: 15 | CJ9: 11 | CK9: 29 | CL9: 16 | CM9: 14 | CN9: 22 | CO9: 15 | CP9: 11 | CQ9: 29 | CR9: 11 | CS9: 13 | CU9: 12 | CV9: 14 | CX9: 11 | CY9: 12 | DA9: 13 | DB9: 10 | DD9: 24 | DE9: 23 | DF9: 47 | DG9: 21 | DH9: 24 | DI9: 49 | DJ9: 11 | DK9: 13 | DM9: 12 | DN9: 14 | DP9: 11 | DQ9: 13 | DS9: 12 | DT9: 14 | DV9: 11 | DW9: 13 | DY9: 12 | DZ9: 14 | EB9: 22 | EC9: 41 | ED9: 53 | EE9: 30 | EF9: 31 | EG9: 55 | EH9: 23 | EI9: 34 | EJ9: 53 | EK9: 23 | EL9: 28 | EM9: 51 | EN9: =SUM(L9,R9,X9,AD9,AJ9,AP9,AV9,BB9,BH9,BN9,BT9,BZ9,CF9,CL9,CR9,CX9,DD9,DJ9,DP9,DV9,EB9,EH9)/BULLETIN!$B$38*100 -> 47.118644 | EO9: =RANK(EN9,$EN$3:$EN$72)&"e" -> 5e | EP9: =SUM(M9,S9,Y9,AE9,AK9,AQ9,AW9,BC9,BI9,BO9,BU9,CA9,CG9,CS9,CY9,DE9,DK9,DQ9,EC9,EI9,CM9,DW9)/BULLETIN!$C$38*100 -> 53.559322 | EQ9: =RANK(EP9,$EP$3:$EP$72)&"e" -> 3e | ER9: =SUM(N9,T9,Z9,AF9,AL9,AR9,AX9,BD9,BJ9,BP9,BV9,CB9,CH9,CT9,CZ9,DF9,DL9,DR9,ED9,EJ9,CN9,DX9)/BULLETIN!$D$38*100 -> 33.305085 | ES9: =RANK(ER9,$ER$3:$ER$72)&"e" -> 5e | ET9: =SUM(L9:N9,R9:T9,X9:Z9,AD9:AF9,AJ9:AL9,AP9:AR9,AV9:AX9,BB9:BD9,BH9:BJ9,BN9:BP9,BT9:BV9,BZ9:CB9,CF9:CH9,CR9:CT9,CX9:CZ9,DD9:DF9,DJ9:DL9,DP9:DR9,EB9:ED9,EH9:EJ9,CL9:CN9,DV9:DX9)/BULLETIN!$E$38*100 -> 41.822034 | EU9: =RANK(ET9,$ET$3:$ET$72)&"e" -> 4e | EV9: =SUM(O9,U9,AA9,AG9,AM9,AS9,AY9,BE9,BK9,BQ9,BW9,CC9,CI9,CU9,DA9,DG9,DM9,DS9,EE9,EK9,CO9,DY9)/BULLETIN!$F$38*100 -> 48.813559 | EW9: =RANK(EV9,$EV$3:$EV$72)&"e" -> 2e | EX9: =SUM(P9,V9,AB9,AH9,AN9,AT9,AZ9,BF9,BL9,BR9,BX9,CD9,CJ9,CV9,DB9,DH9,DN9,DS9,EF9,EL9,CP9,DZ9)/BULLETIN!$G$38*100 -> 49.830508 | EY9: =RANK(EX9,$EX$3:$EX$72)&"e" -> 2e | EZ9: =SUM(Q9,W9,AC9,AI9,AO9,AU9,BA9,BG9,BM9,BS9,BY9,CE9,CK9,CW9,DC9,DI9,DO9,DU9,EG9,EM9,EA9,CQ9)/BULLETIN!$H$38*100 -> 34.661017 | FA9: =RANK(EZ9,$EZ$3:$EZ$72)&"e" -> 2e | FB9: =SUM(O9:Q9,U9:W9,AA9:AC9,AG9:AI9,AM9:AO9,AS9:AU9,AY9:BA9,BE9:BG9,BK9:BM9,BQ9:BS9,BW9:BY9,CC9:CE9,CI9:CK9,CU9:CW9,DA9:DC9,DM9:DO9,DS9:DU9,EE9:EG9,EK9:EM9,DG9:DI9,CO9:CQ9,DY9:EA9)/BULLETIN!$I$38*100 -> 42.076271 | FC9: =RANK(FB9,$FB$3:$FB$72)&"e" -> 1e | FD9: =SUM(L9:EM9)/BULLETIN!$J$38*100 -> 41.949153 | FE9: =RANK(FD9,$FD$3:$FD$72)&"e" -> 2e
A10: MUTOMBA KAZADI Evodie | B10: CO1118 | C10: F | D10: 40371 | E10: 2ème H.P | F10: PERM08 | G10: Haut-Lomami | H10: Lubumbashi | I10: Ruashi | J10: C.S EXCEL | K10: 710008 | L10: 4 | M10: 8 | N10: 14 | O10: 6 | P10: 9 | Q10: 9 | R10: 8 | S10: 8 | T10: 10 | U10: 4 | V10: 5 | W10: 11 | X10: 10 | Y10: 5 | Z10: 12 | AA10: 7 | AB10: 5 | AC10: 11 | AD10: 10 | AE10: 5 | AF10: 12 | AG10: 7 | AH10: 5 | AI10: 9 | AJ10: 11 | AK10: 10 | AL10: 20 | AM10: 10 | AN10: 9 | AO10: 22 | AP10: 9 | AQ10: 10 | AR10: 20 | AS10: 12 | AT10: 11 | AU10: 22 | AV10: 9 | AW10: 10 | AX10: 20 | AY10: 12 | AZ10: 11 | BA10: 22 | BB10: 10 | BC10: 11 | BD10: 22 | BE10: 11 | BF10: 9 | BG10: 22 | BH10: 11 | BI10: 16 | BJ10: 26 | BK10: 15 | BL10: 14 | BM10: 9 | BN10: 11 | BO10: 14 | BP10: 23 | BQ10: 15 | BR10: 11 | BS10: 22 | BT10: 13 | BU10: 12 | BW10: 9 | BX10: 10 | BZ10: 11 | CA10: 14 | CB10: 23 | CC10: 15 | CD10: 11 | CE10: 22 | CF10: 11 | CG10: 14 | CH10: 23 | CI10: 15 | CJ10: 11 | CK10: 22 | CL10: 11 | CM10: 14 | CN10: 23 | CO10: 15 | CP10: 11 | CQ10: 22 | CR10: 10 | CS10: 10 | CU10: 10 | CV10: 13 | CX10: 17 | CY10: 9 | DA10: 11 | DB10: 11 | DD10: 25 | DE10: 22 | DF10: 43 | DG10: 20 | DH10: 20 | DI10: 49 | DJ10: 10 | DK10: 10 | DM10: 10 | DN10: 13 | DP10: 10 | DQ10: 10 | DS10: 10 | DT10: 13 | DV10: 10 | DW10: 10 | DY10: 10 | DZ10: 13 | EB10: 41 | EC10: 40 | ED10: 51 | EE10: 45 | EF10: 35 | EG10: 58 | EH10: 28 | EI10: 30 | EJ10: 55 | EK10: 17 | EL10: 31 | EM10: 54 | EN10: =SUM(L10,R10,X10,AD10,AJ10,AP10,AV10,BB10,BH10,BN10,BT10,BZ10,CF10,CL10,CR10,CX10,DD10,DJ10,DP10,DV10,EB10,EH10)/BULLETIN!$B$38*100 -> 49.152542 | EO10: =RANK(EN10,$EN$3:$EN$72)&"e" -> 2e | EP10: =SUM(M10,S10,Y10,AE10,AK10,AQ10,AW10,BC10,BI10,BO10,BU10,CA10,CG10,CS10,CY10,DE10,DK10,DQ10,EC10,EI10,CM10,DW10)/BULLETIN!$C$38*100 -> 49.491525 | EQ10: =RANK(EP10,$EP$3:$EP$72)&"e" -> 5e | ER10: =SUM(N10,T10,Z10,AF10,AL10,AR10,AX10,BD10,BJ10,BP10,BV10,CB10,CH10,CT10,CZ10,DF10,DL10,DR10,ED10,EJ10,CN10,DX10)/BULLETIN!$D$38*100 -> 33.644068 | ES10: =RANK(ER10,$ER$3:$ER$72)&"e" -> 2e | ET10: =SUM(L10:N10,R10:T10,X10:Z10,AD10:AF10,AJ10:AL10,AP10:AR10,AV10:AX10,BB10:BD10,BH10:BJ10,BN10:BP10,BT10:BV10,BZ10:CB10,CF10:CH10,CR10:CT10,CX10:CZ10,DD10:DF10,DJ10:DL10,DP10:DR10,EB10:ED10,EH10:EJ10,CL10:CN10,DV10:DX10)/BULLETIN!$E$38*100 -> 41.483051 | EU10: =RANK(ET10,$ET$3:$ET$72)&"e" -> 5e | EV10: =SUM(O10,U10,AA10,AG10,AM10,AS10,AY10,BE10,BK10,BQ10,BW10,CC10,CI10,CU10,DA10,DG10,DM10,DS10,EE10,EK10,CO10,DY10)/BULLETIN!$F$38*100 -> 48.474576 | EW10: =RANK(EV10,$EV$3:$EV$72)&"e" -> 3e | EX10: =SUM(P10,V10,AB10,AH10,AN10,AT10,AZ10,BF10,BL10,BR10,BX10,CD10,CJ10,CV10,DB10,DH10,DN10,DS10,EF10,EL10,CP10,DZ10)/BULLETIN!$G$38*100 -> 47.118644 | EY10: =RANK(EX10,$EX$3:$EX$72)&"e" -> 6e | EZ10: =SUM(Q10,W10,AC10,AI10,AO10,AU10,BA10,BG10,BM10,BS10,BY10,CE10,CK10,CW10,DC10,DI10,DO10,DU10,EG10,EM10,EA10,CQ10)/BULLETIN!$H$38*100 -> 32.711864 | FA10: =RANK(EZ10,$EZ$3:$EZ$72)&"e" -> 5e | FB10: =SUM(O10:Q10,U10:W10,AA10:AC10,AG10:AI10,AM10:AO10,AS10:AU10,AY10:BA10,BE10:BG10,BK10:BM10,BQ10:BS10,BW10:BY10,CC10:CE10,CI10:CK10,CU10:CW10,DA10:DC10,DM10:DO10,DS10:DU10,EE10:EG10,EK10:EM10,DG10:DI10,CO10:CQ10,DY10:EA10)/BULLETIN!$I$38*100 -> 40.381356 | FC10: =RANK(FB10,$FB$3:$FB$72)&"e" -> 4e | FD10: =SUM(L10:EM10)/BULLETIN!$J$38*100 -> 40.932203 | FE10: =RANK(FD10,$FD$3:$FD$72)&"e" -> 5e
A11: KALENGA BUKASA | B11: CO1119 | C11: M | D11: 40068 | E11: 2ème H.P | F11: PERM09 | G11: Haut-Katanga | H11: Lubumbashi | I11: Annexe | J11: C.S EXCEL | K11: 710009 | L11: 3 | M11: 4 | N11: 11 | O11: 6 | P11: 7 | Q11: 10 | R11: 6 | S11: 6 | T11: 9 | U11: 6 | V11: 4 | W11: 11 | X11: 8 | Y11: 3 | Z11: 9 | AA11: 4 | AB11: 5 | AC11: 9 | AD11: 8 | AE11: 3 | AF11: 9 | AG11: 4 | AH11: 5 | AI11: 9 | AJ11: 5 | AK11: 6 | AL11: 22 | AM11: 7 | AN11: 3 | AO11: 22 | AP11: 11 | AQ11: 11 | AR11: 22 | AS11: 12 | AT11: 13 | AU11: 22 | AV11: 11 | AW11: 11 | AX11: 22 | AY11: 12 | AZ11: 13 | BA11: 22 | BB11: 12 | BC11: 11 | BD11: 22 | BE11: 11 | BF11: 11 | BG11: 21 | BH11: 9 | BI11: 12 | BJ11: 23 | BK11: 12 | BL11: 11 | BM11: 9 | BN11: 11 | BO11: 17 | BP11: 23 | BQ11: 12 | BR11: 13 | BS11: 20 | BT11: 15 | BU11: 12 | BW11: 12 | BX11: 11 | BZ11: 11 | CA11: 17 | CB11: 23 | CC11: 12 | CD11: 13 | CE11: 20 | CF11: 11 | CG11: 17 | CH11: 23 | CI11: 12 | CJ11: 13 | CK11: 20 | CL11: 11 | CM11: 17 | CN11: 23 | CO11: 12 | CP11: 13 | CQ11: 20 | CR11: 11 | CS11: 12 | CU11: 11 | CV11: 12 | CX11: 14 | CY11: 14 | DA11: 11 | DB11: 11 | DD11: 21 | DE11: 22 | DF11: 44 | DG11: 13 | DH11: 26 | DI11: 43 | DJ11: 11 | DK11: 12 | DM11: 11 | DN11: 12 | DP11: 11 | DQ11: 12 | DS11: 11 | DT11: 12 | DV11: 11 | DW11: 12 | DY11: 11 | DZ11: 12 | EB11: 25 | EC11: 26 | ED11: 54 | EE11: 28 | EF11: 29 | EG11: 49 | EH11: 23 | EI11: 30 | EJ11: 55 | EK11: 33 | EL11: 34 | EM11: 54 | EN11: =SUM(L11,R11,X11,AD11,AJ11,AP11,AV11,BB11,BH11,BN11,BT11,BZ11,CF11,CL11,CR11,CX11,DD11,DJ11,DP11,DV11,EB11,EH11)/BULLETIN!$B$38*100 -> 43.898305 | EO11: =RANK(EN11,$EN$3:$EN$72)&"e" -> 8e | EP11: =SUM(M11,S11,Y11,AE11,AK11,AQ11,AW11,BC11,BI11,BO11,BU11,CA11,CG11,CS11,CY11,DE11,DK11,DQ11,EC11,EI11,CM11,DW11)/BULLETIN!$C$38*100 -> 48.644068 | EQ11: =RANK(EP11,$EP$3:$EP$72)&"e" -> 7e | ER11: =SUM(N11,T11,Z11,AF11,AL11,AR11,AX11,BD11,BJ11,BP11,BV11,CB11,CH11,CT11,CZ11,DF11,DL11,DR11,ED11,EJ11,CN11,DX11)/BULLETIN!$D$38*100 -> 33.389831 | ES11: =RANK(ER11,$ER$3:$ER$72)&"e" -> 4e | ET11: =SUM(L11:N11,R11:T11,X11:Z11,AD11:AF11,AJ11:AL11,AP11:AR11,AV11:AX11,BB11:BD11,BH11:BJ11,BN11:BP11,BT11:BV11,BZ11:CB11,CF11:CH11,CR11:CT11,CX11:CZ11,DD11:DF11,DJ11:DL11,DP11:DR11,EB11:ED11,EH11:EJ11,CL11:CN11,DV11:DX11)/BULLETIN!$E$38*100 -> 39.830508 | EU11: =RANK(ET11,$ET$3:$ET$72)&"e" -> 8e | EV11: =SUM(O11,U11,AA11,AG11,AM11,AS11,AY11,BE11,BK11,BQ11,BW11,CC11,CI11,CU11,DA11,DG11,DM11,DS11,EE11,EK11,CO11,DY11)/BULLETIN!$F$38*100 -> 44.576271 | EW11: =RANK(EV11,$EV$3:$EV$72)&"e" -> 8e | EX11: =SUM(P11,V11,AB11,AH11,AN11,AT11,AZ11,BF11,BL11,BR11,BX11,CD11,CJ11,CV11,DB11,DH11,DN11,DS11,EF11,EL11,CP11,DZ11)/BULLETIN!$G$38*100 -> 47.79661 | EY11: =RANK(EX11,$EX$3:$EX$72)&"e" -> 4e | EZ11: =SUM(Q11,W11,AC11,AI11,AO11,AU11,BA11,BG11,BM11,BS11,BY11,CE11,CK11,CW11,DC11,DI11,DO11,DU11,EG11,EM11,EA11,CQ11)/BULLETIN!$H$38*100 -> 30.59322 | FA11: =RANK(EZ11,$EZ$3:$EZ$72)&"e" -> 9e | FB11: =SUM(O11:Q11,U11:W11,AA11:AC11,AG11:AI11,AM11:AO11,AS11:AU11,AY11:BA11,BE11:BG11,BK11:BM11,BQ11:BS11,BW11:BY11,CC11:CE11,CI11:CK11,CU11:CW11,DA11:DC11,DM11:DO11,DS11:DU11,EE11:EG11,EK11:EM11,DG11:DI11,CO11:CQ11,DY11:EA11)/BULLETIN!$I$38*100 -> 38.432203 | FC11: =RANK(FB11,$FB$3:$FB$72)&"e" -> 8e | FD11: =SUM(L11:EM11)/BULLETIN!$J$38*100 -> 39.131356 | FE11: =RANK(FD11,$FD$3:$FD$72)&"e" -> 8e
A12: KAZADI MWAMBA | EN12: =SUM(L12,R12,X12,AD12,AJ12,AP12,AV12,BB12,BH12,BN12,BT12,BZ12,CF12,CL12,CR12,CX12,DD12,DJ12,DP12,DV12,EB12,EH12)/BULLETIN!$B$38*100 -> 0 | EO12: =RANK(EN12,$EN$3:$EN$72)&"e" -> 10e | EP12: =SUM(M12,S12,Y12,AE12,AK12,AQ12,AW12,BC12,BI12,BO12,BU12,CA12,CG12,CS12,CY12,DE12,DK12,DQ12,EC12,EI12,CM12,DW12)/BULLETIN!$C$38*100 -> 0 | EQ12: =RANK(EP12,$EP$3:$EP$72)&"e" -> 10e | ER12: =SUM(N12,T12,Z12,AF12,AL12,AR12,AX12,BD12,BJ12,BP12,BV12,CB12,CH12,CT12,CZ12,DF12,DL12,DR12,ED12,EJ12,CN12,DX12)/BULLETIN!$D$38*100 -> 0 | ES12: =RANK(ER12,$ER$3:$ER$72)&"e" -> 10e | ET12: =SUM(L12:N12,R12:T12,X12:Z12,AD12:AF12,AJ12:AL12,AP12:AR12,AV12:AX12,BB12:BD12,BH12:BJ12,BN12:BP12,BT12:BV12,BZ12:CB12,CF12:CH12,CR12:CT12,CX12:CZ12,DD12:DF12,DJ12:DL12,DP12:DR12,EB12:ED12,EH12:EJ12,CL12:CN12,DV12:DX12)/BULLETIN!$E$38*100 -> 0 | EU12: =RANK(ET12,$ET$3:$ET$72)&"e" -> 10e | EV12: =SUM(O12,U12,AA12,AG12,AM12,AS12,AY12,BE12,BK12,BQ12,BW12,CC12,CI12,CU12,DA12,DG12,DM12,DS12,EE12,EK12,CO12,DY12)/BULLETIN!$F$38*100 -> 0 | EW12: =RANK(EV12,$EV$3:$EV$72)&"e" -> 10e | EX12: =SUM(P12,V12,AB12,AH12,AN12,AT12,AZ12,BF12,BL12,BR12,BX12,CD12,CJ12,CV12,DB12,DH12,DN12,DS12,EF12,EL12,CP12,DZ12)/BULLETIN!$G$38*100 -> 0 | EY12: =RANK(EX12,$EX$3:$EX$72)&"e" -> 10e | EZ12: =SUM(Q12,W12,AC12,AI12,AO12,AU12,BA12,BG12,BM12,BS12,BY12,CE12,CK12,CW12,DC12,DI12,DO12,DU12,EG12,EM12,EA12,CQ12)/BULLETIN!$H$38*100 -> 0 | FA12: =RANK(EZ12,$EZ$3:$EZ$72)&"e" -> 10e | FB12: =SUM(O12:Q12,U12:W12,AA12:AC12,AG12:AI12,AM12:AO12,AS12:AU12,AY12:BA12,BE12:BG12,BK12:BM12,BQ12:BS12,BW12:BY12,CC12:CE12,CI12:CK12,CU12:CW12,DA12:DC12,DM12:DO12,DS12:DU12,EE12:EG12,EK12:EM12,DG12:DI12,CO12:CQ12,DY12:EA12)/BULLETIN!$I$38*100 -> 0 | FC12: =RANK(FB12,$FB$3:$FB$72)&"e" -> 10e | FD12: =SUM(L12:EM12)/BULLETIN!$J$38*100 -> 0 | FE12: =RANK(FD12,$FD$3:$FD$72)&"e" -> 10e
EN13: =SUM(L13,R13,X13,AD13,AJ13,AP13,AV13,BB13,BH13,BN13,BT13,BZ13,CF13,CL13,CR13,CX13,DD13,DJ13,DP13,DV13,EB13,EH13)/BULLETIN!$B$38*100 -> 0 | EO13: =RANK(EN13,$EN$3:$EN$72)&"e" -> 10e | EP13: =SUM(M13,S13,Y13,AE13,AK13,AQ13,AW13,BC13,BI13,BO13,BU13,CA13,CG13,CS13,CY13,DE13,DK13,DQ13,EC13,EI13,CM13,DW13)/BULLETIN!$C$38*100 -> 0 | EQ13: =RANK(EP13,$EP$3:$EP$72)&"e" -> 10e | ER13: =SUM(N13,T13,Z13,AF13,AL13,AR13,AX13,BD13,BJ13,BP13,BV13,CB13,CH13,CT13,CZ13,DF13,DL13,DR13,ED13,EJ13,CN13,DX13)/BULLETIN!$D$38*100 -> 0 | ES13: =RANK(ER13,$ER$3:$ER$72)&"e" -> 10e | ET13: =SUM(L13:N13,R13:T13,X13:Z13,AD13:AF13,AJ13:AL13,AP13:AR13,AV13:AX13,BB13:BD13,BH13:BJ13,BN13:BP13,BT13:BV13,BZ13:CB13,CF13:CH13,CR13:CT13,CX13:CZ13,DD13:DF13,DJ13:DL13,DP13:DR13,EB13:ED13,EH13:EJ13,CL13:CN13,DV13:DX13)/BULLETIN!$E$38*100 -> 0 | EU13: =RANK(ET13,$ET$3:$ET$72)&"e" -> 10e | EV13: =SUM(O13,U13,AA13,AG13,AM13,AS13,AY13,BE13,BK13,BQ13,BW13,CC13,CI13,CU13,DA13,DG13,DM13,DS13,EE13,EK13,CO13,DY13)/BULLETIN!$F$38*100 -> 0 | EW13: =RANK(EV13,$EV$3:$EV$72)&"e" -> 10e | EX13: =SUM(P13,V13,AB13,AH13,AN13,AT13,AZ13,BF13,BL13,BR13,BX13,CD13,CJ13,CV13,DB13,DH13,DN13,DS13,EF13,EL13,CP13,DZ13)/BULLETIN!$G$38*100 -> 0 | EY13: =RANK(EX13,$EX$3:$EX$72)&"e" -> 10e | EZ13: =SUM(Q13,W13,AC13,AI13,AO13,AU13,BA13,BG13,BM13,BS13,BY13,CE13,CK13,CW13,DC13,DI13,DO13,DU13,EG13,EM13,EA13,CQ13)/BULLETIN!$H$38*100 -> 0 | FA13: =RANK(EZ13,$EZ$3:$EZ$72)&"e" -> 10e | FB13: =SUM(O13:Q13,U13:W13,AA13:AC13,AG13:AI13,AM13:AO13,AS13:AU13,AY13:BA13,BE13:BG13,BK13:BM13,BQ13:BS13,BW13:BY13,CC13:CE13,CI13:CK13,CU13:CW13,DA13:DC13,DM13:DO13,DS13:DU13,EE13:EG13,EK13:EM13,DG13:DI13,CO13:CQ13,DY13:EA13)/BULLETIN!$I$38*100 -> 0 | FC13: =RANK(FB13,$FB$3:$FB$72)&"e" -> 10e | FD13: =SUM(L13:EM13)/BULLETIN!$J$38*100 -> 0 | FE13: =RANK(FD13,$FD$3:$FD$72)&"e" -> 10e
EN14: =SUM(L14,R14,X14,AD14,AJ14,AP14,AV14,BB14,BH14,BN14,BT14,BZ14,CF14,CL14,CR14,CX14,DD14,DJ14,DP14,DV14,EB14,EH14)/BULLETIN!$B$38*100 -> 0 | EO14: =RANK(EN14,$EN$3:$EN$72)&"e" -> 10e | EP14: =SUM(M14,S14,Y14,AE14,AK14,AQ14,AW14,BC14,BI14,BO14,BU14,CA14,CG14,CS14,CY14,DE14,DK14,DQ14,EC14,EI14,CM14,DW14)/BULLETIN!$C$38*100 -> 0 | EQ14: =RANK(EP14,$EP$3:$EP$72)&"e" -> 10e | ER14: =SUM(N14,T14,Z14,AF14,AL14,AR14,AX14,BD14,BJ14,BP14,BV14,CB14,CH14,CT14,CZ14,DF14,DL14,DR14,ED14,EJ14,CN14,DX14)/BULLETIN!$D$38*100 -> 0 | ES14: =RANK(ER14,$ER$3:$ER$72)&"e" -> 10e | ET14: =SUM(L14:N14,R14:T14,X14:Z14,AD14:AF14,AJ14:AL14,AP14:AR14,AV14:AX14,BB14:BD14,BH14:BJ14,BN14:BP14,BT14:BV14,BZ14:CB14,CF14:CH14,CR14:CT14,CX14:CZ14,DD14:DF14,DJ14:DL14,DP14:DR14,EB14:ED14,EH14:EJ14,CL14:CN14,DV14:DX14)/BULLETIN!$E$38*100 -> 0 | EU14: =RANK(ET14,$ET$3:$ET$72)&"e" -> 10e | EV14: =SUM(O14,U14,AA14,AG14,AM14,AS14,AY14,BE14,BK14,BQ14,BW14,CC14,CI14,CU14,DA14,DG14,DM14,DS14,EE14,EK14,CO14,DY14)/BULLETIN!$F$38*100 -> 0 | EW14: =RANK(EV14,$EV$3:$EV$72)&"e" -> 10e | EX14: =SUM(P14,V14,AB14,AH14,AN14,AT14,AZ14,BF14,BL14,BR14,BX14,CD14,CJ14,CV14,DB14,DH14,DN14,DS14,EF14,EL14,CP14,DZ14)/BULLETIN!$G$38*100 -> 0 | EY14: =RANK(EX14,$EX$3:$EX$72)&"e" -> 10e | EZ14: =SUM(Q14,W14,AC14,AI14,AO14,AU14,BA14,BG14,BM14,BS14,BY14,CE14,CK14,CW14,DC14,DI14,DO14,DU14,EG14,EM14,EA14,CQ14)/BULLETIN!$H$38*100 -> 0 | FA14: =RANK(EZ14,$EZ$3:$EZ$72)&"e" -> 10e | FB14: =SUM(O14:Q14,U14:W14,AA14:AC14,AG14:AI14,AM14:AO14,AS14:AU14,AY14:BA14,BE14:BG14,BK14:BM14,BQ14:BS14,BW14:BY14,CC14:CE14,CI14:CK14,CU14:CW14,DA14:DC14,DM14:DO14,DS14:DU14,EE14:EG14,EK14:EM14,DG14:DI14,CO14:CQ14,DY14:EA14)/BULLETIN!$I$38*100 -> 0 | FC14: =RANK(FB14,$FB$3:$FB$72)&"e" -> 10e | FD14: =SUM(L14:EM14)/BULLETIN!$J$38*100 -> 0 | FE14: =RANK(FD14,$FD$3:$FD$72)&"e" -> 10e
EN15: =SUM(L15,R15,X15,AD15,AJ15,AP15,AV15,BB15,BH15,BN15,BT15,BZ15,CF15,CL15,CR15,CX15,DD15,DJ15,DP15,DV15,EB15,EH15)/BULLETIN!$B$38*100 -> 0 | EO15: =RANK(EN15,$EN$3:$EN$72)&"e" -> 10e | EP15: =SUM(M15,S15,Y15,AE15,AK15,AQ15,AW15,BC15,BI15,BO15,BU15,CA15,CG15,CS15,CY15,DE15,DK15,DQ15,EC15,EI15,CM15,DW15)/BULLETIN!$C$38*100 -> 0 | EQ15: =RANK(EP15,$EP$3:$EP$72)&"e" -> 10e | ER15: =SUM(N15,T15,Z15,AF15,AL15,AR15,AX15,BD15,BJ15,BP15,BV15,CB15,CH15,CT15,CZ15,DF15,DL15,DR15,ED15,EJ15,CN15,DX15)/BULLETIN!$D$38*100 -> 0 | ES15: =RANK(ER15,$ER$3:$ER$72)&"e" -> 10e | ET15: =SUM(L15:N15,R15:T15,X15:Z15,AD15:AF15,AJ15:AL15,AP15:AR15,AV15:AX15,BB15:BD15,BH15:BJ15,BN15:BP15,BT15:BV15,BZ15:CB15,CF15:CH15,CR15:CT15,CX15:CZ15,DD15:DF15,DJ15:DL15,DP15:DR15,EB15:ED15,EH15:EJ15,CL15:CN15,DV15:DX15)/BULLETIN!$E$38*100 -> 0 | EU15: =RANK(ET15,$ET$3:$ET$72)&"e" -> 10e | EV15: =SUM(O15,U15,AA15,AG15,AM15,AS15,AY15,BE15,BK15,BQ15,BW15,CC15,CI15,CU15,DA15,DG15,DM15,DS15,EE15,EK15,CO15,DY15)/BULLETIN!$F$38*100 -> 0 | EW15: =RANK(EV15,$EV$3:$EV$72)&"e" -> 10e | EX15: =SUM(P15,V15,AB15,AH15,AN15,AT15,AZ15,BF15,BL15,BR15,BX15,CD15,CJ15,CV15,DB15,DH15,DN15,DS15,EF15,EL15,CP15,DZ15)/BULLETIN!$G$38*100 -> 0 | EY15: =RANK(EX15,$EX$3:$EX$72)&"e" -> 10e | EZ15: =SUM(Q15,W15,AC15,AI15,AO15,AU15,BA15,BG15,BM15,BS15,BY15,CE15,CK15,CW15,DC15,DI15,DO15,DU15,EG15,EM15,EA15,CQ15)/BULLETIN!$H$38*100 -> 0 | FA15: =RANK(EZ15,$EZ$3:$EZ$72)&"e" -> 10e | FB15: =SUM(O15:Q15,U15:W15,AA15:AC15,AG15:AI15,AM15:AO15,AS15:AU15,AY15:BA15,BE15:BG15,BK15:BM15,BQ15:BS15,BW15:BY15,CC15:CE15,CI15:CK15,CU15:CW15,DA15:DC15,DM15:DO15,DS15:DU15,EE15:EG15,EK15:EM15,DG15:DI15,CO15:CQ15,DY15:EA15)/BULLETIN!$I$38*100 -> 0 | FC15: =RANK(FB15,$FB$3:$FB$72)&"e" -> 10e | FD15: =SUM(L15:EM15)/BULLETIN!$J$38*100 -> 0 | FE15: =RANK(FD15,$FD$3:$FD$72)&"e" -> 10e
EN16: =SUM(L16,R16,X16,AD16,AJ16,AP16,AV16,BB16,BH16,BN16,BT16,BZ16,CF16,CL16,CR16,CX16,DD16,DJ16,DP16,DV16,EB16,EH16)/BULLETIN!$B$38*100 -> 0 | EO16: =RANK(EN16,$EN$3:$EN$72)&"e" -> 10e | EP16: =SUM(M16,S16,Y16,AE16,AK16,AQ16,AW16,BC16,BI16,BO16,BU16,CA16,CG16,CS16,CY16,DE16,DK16,DQ16,EC16,EI16,CM16,DW16)/BULLETIN!$C$38*100 -> 0 | EQ16: =RANK(EP16,$EP$3:$EP$72)&"e" -> 10e | ER16: =SUM(N16,T16,Z16,AF16,AL16,AR16,AX16,BD16,BJ16,BP16,BV16,CB16,CH16,CT16,CZ16,DF16,DL16,DR16,ED16,EJ16,CN16,DX16)/BULLETIN!$D$38*100 -> 0 | ES16: =RANK(ER16,$ER$3:$ER$72)&"e" -> 10e | ET16: =SUM(L16:N16,R16:T16,X16:Z16,AD16:AF16,AJ16:AL16,AP16:AR16,AV16:AX16,BB16:BD16,BH16:BJ16,BN16:BP16,BT16:BV16,BZ16:CB16,CF16:CH16,CR16:CT16,CX16:CZ16,DD16:DF16,DJ16:DL16,DP16:DR16,EB16:ED16,EH16:EJ16,CL16:CN16,DV16:DX16)/BULLETIN!$E$38*100 -> 0 | EU16: =RANK(ET16,$ET$3:$ET$72)&"e" -> 10e | EV16: =SUM(O16,U16,AA16,AG16,AM16,AS16,AY16,BE16,BK16,BQ16,BW16,CC16,CI16,CU16,DA16,DG16,DM16,DS16,EE16,EK16,CO16,DY16)/BULLETIN!$F$38*100 -> 0 | EW16: =RANK(EV16,$EV$3:$EV$72)&"e" -> 10e | EX16: =SUM(P16,V16,AB16,AH16,AN16,AT16,AZ16,BF16,BL16,BR16,BX16,CD16,CJ16,CV16,DB16,DH16,DN16,DS16,EF16,EL16,CP16,DZ16)/BULLETIN!$G$38*100 -> 0 | EY16: =RANK(EX16,$EX$3:$EX$72)&"e" -> 10e | EZ16: =SUM(Q16,W16,AC16,AI16,AO16,AU16,BA16,BG16,BM16,BS16,BY16,CE16,CK16,CW16,DC16,DI16,DO16,DU16,EG16,EM16,EA16,CQ16)/BULLETIN!$H$38*100 -> 0 | FA16: =RANK(EZ16,$EZ$3:$EZ$72)&"e" -> 10e | FB16: =SUM(O16:Q16,U16:W16,AA16:AC16,AG16:AI16,AM16:AO16,AS16:AU16,AY16:BA16,BE16:BG16,BK16:BM16,BQ16:BS16,BW16:BY16,CC16:CE16,CI16:CK16,CU16:CW16,DA16:DC16,DM16:DO16,DS16:DU16,EE16:EG16,EK16:EM16,DG16:DI16,CO16:CQ16,DY16:EA16)/BULLETIN!$I$38*100 -> 0 | FC16: =RANK(FB16,$FB$3:$FB$72)&"e" -> 10e | FD16: =SUM(L16:EM16)/BULLETIN!$J$38*100 -> 0 | FE16: =RANK(FD16,$FD$3:$FD$72)&"e" -> 10e
EN17: =SUM(L17,R17,X17,AD17,AJ17,AP17,AV17,BB17,BH17,BN17,BT17,BZ17,CF17,CL17,CR17,CX17,DD17,DJ17,DP17,DV17,EB17,EH17)/BULLETIN!$B$38*100 -> 0 | EO17: =RANK(EN17,$EN$3:$EN$72)&"e" -> 10e | EP17: =SUM(M17,S17,Y17,AE17,AK17,AQ17,AW17,BC17,BI17,BO17,BU17,CA17,CG17,CS17,CY17,DE17,DK17,DQ17,EC17,EI17,CM17,DW17)/BULLETIN!$C$38*100 -> 0 | EQ17: =RANK(EP17,$EP$3:$EP$72)&"e" -> 10e | ER17: =SUM(N17,T17,Z17,AF17,AL17,AR17,AX17,BD17,BJ17,BP17,BV17,CB17,CH17,CT17,CZ17,DF17,DL17,DR17,ED17,EJ17,CN17,DX17)/BULLETIN!$D$38*100 -> 0 | ES17: =RANK(ER17,$ER$3:$ER$72)&"e" -> 10e | ET17: =SUM(L17:N17,R17:T17,X17:Z17,AD17:AF17,AJ17:AL17,AP17:AR17,AV17:AX17,BB17:BD17,BH17:BJ17,BN17:BP17,BT17:BV17,BZ17:CB17,CF17:CH17,CR17:CT17,CX17:CZ17,DD17:DF17,DJ17:DL17,DP17:DR17,EB17:ED17,EH17:EJ17,CL17:CN17,DV17:DX17)/BULLETIN!$E$38*100 -> 0 | EU17: =RANK(ET17,$ET$3:$ET$72)&"e" -> 10e | EV17: =SUM(O17,U17,AA17,AG17,AM17,AS17,AY17,BE17,BK17,BQ17,BW17,CC17,CI17,CU17,DA17,DG17,DM17,DS17,EE17,EK17,CO17,DY17)/BULLETIN!$F$38*100 -> 0 | EW17: =RANK(EV17,$EV$3:$EV$72)&"e" -> 10e | EX17: =SUM(P17,V17,AB17,AH17,AN17,AT17,AZ17,BF17,BL17,BR17,BX17,CD17,CJ17,CV17,DB17,DH17,DN17,DS17,EF17,EL17,CP17,DZ17)/BULLETIN!$G$38*100 -> 0 | EY17: =RANK(EX17,$EX$3:$EX$72)&"e" -> 10e | EZ17: =SUM(Q17,W17,AC17,AI17,AO17,AU17,BA17,BG17,BM17,BS17,BY17,CE17,CK17,CW17,DC17,DI17,DO17,DU17,EG17,EM17,EA17,CQ17)/BULLETIN!$H$38*100 -> 0 | FA17: =RANK(EZ17,$EZ$3:$EZ$72)&"e" -> 10e | FB17: =SUM(O17:Q17,U17:W17,AA17:AC17,AG17:AI17,AM17:AO17,AS17:AU17,AY17:BA17,BE17:BG17,BK17:BM17,BQ17:BS17,BW17:BY17,CC17:CE17,CI17:CK17,CU17:CW17,DA17:DC17,DM17:DO17,DS17:DU17,EE17:EG17,EK17:EM17,DG17:DI17,CO17:CQ17,DY17:EA17)/BULLETIN!$I$38*100 -> 0 | FC17: =RANK(FB17,$FB$3:$FB$72)&"e" -> 10e | FD17: =SUM(L17:EM17)/BULLETIN!$J$38*100 -> 0 | FE17: =RANK(FD17,$FD$3:$FD$72)&"e" -> 10e
EN18: =SUM(L18,R18,X18,AD18,AJ18,AP18,AV18,BB18,BH18,BN18,BT18,BZ18,CF18,CL18,CR18,CX18,DD18,DJ18,DP18,DV18,EB18,EH18)/BULLETIN!$B$38*100 -> 0 | EO18: =RANK(EN18,$EN$3:$EN$72)&"e" -> 10e | EP18: =SUM(M18,S18,Y18,AE18,AK18,AQ18,AW18,BC18,BI18,BO18,BU18,CA18,CG18,CS18,CY18,DE18,DK18,DQ18,EC18,EI18,CM18,DW18)/BULLETIN!$C$38*100 -> 0 | EQ18: =RANK(EP18,$EP$3:$EP$72)&"e" -> 10e | ER18: =SUM(N18,T18,Z18,AF18,AL18,AR18,AX18,BD18,BJ18,BP18,BV18,CB18,CH18,CT18,CZ18,DF18,DL18,DR18,ED18,EJ18,CN18,DX18)/BULLETIN!$D$38*100 -> 0 | ES18: =RANK(ER18,$ER$3:$ER$72)&"e" -> 10e | ET18: =SUM(L18:N18,R18:T18,X18:Z18,AD18:AF18,AJ18:AL18,AP18:AR18,AV18:AX18,BB18:BD18,BH18:BJ18,BN18:BP18,BT18:BV18,BZ18:CB18,CF18:CH18,CR18:CT18,CX18:CZ18,DD18:DF18,DJ18:DL18,DP18:DR18,EB18:ED18,EH18:EJ18,CL18:CN18,DV18:DX18)/BULLETIN!$E$38*100 -> 0 | EU18: =RANK(ET18,$ET$3:$ET$72)&"e" -> 10e | EV18: =SUM(O18,U18,AA18,AG18,AM18,AS18,AY18,BE18,BK18,BQ18,BW18,CC18,CI18,CU18,DA18,DG18,DM18,DS18,EE18,EK18,CO18,DY18)/BULLETIN!$F$38*100 -> 0 | EW18: =RANK(EV18,$EV$3:$EV$72)&"e" -> 10e | EX18: =SUM(P18,V18,AB18,AH18,AN18,AT18,AZ18,BF18,BL18,BR18,BX18,CD18,CJ18,CV18,DB18,DH18,DN18,DS18,EF18,EL18,CP18,DZ18)/BULLETIN!$G$38*100 -> 0 | EY18: =RANK(EX18,$EX$3:$EX$72)&"e" -> 10e | EZ18: =SUM(Q18,W18,AC18,AI18,AO18,AU18,BA18,BG18,BM18,BS18,BY18,CE18,CK18,CW18,DC18,DI18,DO18,DU18,EG18,EM18,EA18,CQ18)/BULLETIN!$H$38*100 -> 0 | FA18: =RANK(EZ18,$EZ$3:$EZ$72)&"e" -> 10e | FB18: =SUM(O18:Q18,U18:W18,AA18:AC18,AG18:AI18,AM18:AO18,AS18:AU18,AY18:BA18,BE18:BG18,BK18:BM18,BQ18:BS18,BW18:BY18,CC18:CE18,CI18:CK18,CU18:CW18,DA18:DC18,DM18:DO18,DS18:DU18,EE18:EG18,EK18:EM18,DG18:DI18,CO18:CQ18,DY18:EA18)/BULLETIN!$I$38*100 -> 0 | FC18: =RANK(FB18,$FB$3:$FB$72)&"e" -> 10e | FD18: =SUM(L18:EM18)/BULLETIN!$J$38*100 -> 0 | FE18: =RANK(FD18,$FD$3:$FD$72)&"e" -> 10e
EN19: =SUM(L19,R19,X19,AD19,AJ19,AP19,AV19,BB19,BH19,BN19,BT19,BZ19,CF19,CL19,CR19,CX19,DD19,DJ19,DP19,DV19,EB19,EH19)/BULLETIN!$B$38*100 -> 0 | EO19: =RANK(EN19,$EN$3:$EN$72)&"e" -> 10e | EP19: =SUM(M19,S19,Y19,AE19,AK19,AQ19,AW19,BC19,BI19,BO19,BU19,CA19,CG19,CS19,CY19,DE19,DK19,DQ19,EC19,EI19,CM19,DW19)/BULLETIN!$C$38*100 -> 0 | EQ19: =RANK(EP19,$EP$3:$EP$72)&"e" -> 10e | ER19: =SUM(N19,T19,Z19,AF19,AL19,AR19,AX19,BD19,BJ19,BP19,BV19,CB19,CH19,CT19,CZ19,DF19,DL19,DR19,ED19,EJ19,CN19,DX19)/BULLETIN!$D$38*100 -> 0 | ES19: =RANK(ER19,$ER$3:$ER$72)&"e" -> 10e | ET19: =SUM(L19:N19,R19:T19,X19:Z19,AD19:AF19,AJ19:AL19,AP19:AR19,AV19:AX19,BB19:BD19,BH19:BJ19,BN19:BP19,BT19:BV19,BZ19:CB19,CF19:CH19,CR19:CT19,CX19:CZ19,DD19:DF19,DJ19:DL19,DP19:DR19,EB19:ED19,EH19:EJ19,CL19:CN19,DV19:DX19)/BULLETIN!$E$38*100 -> 0 | EU19: =RANK(ET19,$ET$3:$ET$72)&"e" -> 10e | EV19: =SUM(O19,U19,AA19,AG19,AM19,AS19,AY19,BE19,BK19,BQ19,BW19,CC19,CI19,CU19,DA19,DG19,DM19,DS19,EE19,EK19,CO19,DY19)/BULLETIN!$F$38*100 -> 0 | EW19: =RANK(EV19,$EV$3:$EV$72)&"e" -> 10e | EX19: =SUM(P19,V19,AB19,AH19,AN19,AT19,AZ19,BF19,BL19,BR19,BX19,CD19,CJ19,CV19,DB19,DH19,DN19,DS19,EF19,EL19,CP19,DZ19)/BULLETIN!$G$38*100 -> 0 | EY19: =RANK(EX19,$EX$3:$EX$72)&"e" -> 10e | EZ19: =SUM(Q19,W19,AC19,AI19,AO19,AU19,BA19,BG19,BM19,BS19,BY19,CE19,CK19,CW19,DC19,DI19,DO19,DU19,EG19,EM19,EA19,CQ19)/BULLETIN!$H$38*100 -> 0 | FA19: =RANK(EZ19,$EZ$3:$EZ$72)&"e" -> 10e | FB19: =SUM(O19:Q19,U19:W19,AA19:AC19,AG19:AI19,AM19:AO19,AS19:AU19,AY19:BA19,BE19:BG19,BK19:BM19,BQ19:BS19,BW19:BY19,CC19:CE19,CI19:CK19,CU19:CW19,DA19:DC19,DM19:DO19,DS19:DU19,EE19:EG19,EK19:EM19,DG19:DI19,CO19:CQ19,DY19:EA19)/BULLETIN!$I$38*100 -> 0 | FC19: =RANK(FB19,$FB$3:$FB$72)&"e" -> 10e | FD19: =SUM(L19:EM19)/BULLETIN!$J$38*100 -> 0 | FE19: =RANK(FD19,$FD$3:$FD$72)&"e" -> 10e
